%(asime)s:%(filename)s:%(name)s:%(levelname)s:%(message)s
2022-01-30 21:17:17,494:utility.py:logger_expt:ERROR:Foreign key associated with column 'customer_account.account_id' could not find table 'bankaccount' with which to generate a foreign key to target column 'id'
Traceback (most recent call last):
  File "C:\Users\huang\OneDrive\14-code\bank\database.py", line 90, in new_rec_in_db
    session.commit()
  File "C:\ProgramData\Anaconda3\envs\bank\lib\site-packages\sqlalchemy\orm\session.py", line 1428, in commit
    self._transaction.commit(_to_root=self.future)
  File "C:\ProgramData\Anaconda3\envs\bank\lib\site-packages\sqlalchemy\orm\session.py", line 829, in commit
    self._prepare_impl()
  File "C:\ProgramData\Anaconda3\envs\bank\lib\site-packages\sqlalchemy\orm\session.py", line 808, in _prepare_impl
    self.session.flush()
  File "C:\ProgramData\Anaconda3\envs\bank\lib\site-packages\sqlalchemy\orm\session.py", line 3345, in flush
    self._flush(objects)
  File "C:\ProgramData\Anaconda3\envs\bank\lib\site-packages\sqlalchemy\orm\session.py", line 3485, in _flush
    transaction.rollback(_capture_exception=True)
  File "C:\ProgramData\Anaconda3\envs\bank\lib\site-packages\sqlalchemy\util\langhelpers.py", line 70, in __exit__
    compat.raise_(
  File "C:\ProgramData\Anaconda3\envs\bank\lib\site-packages\sqlalchemy\util\compat.py", line 207, in raise_
    raise exception
  File "C:\ProgramData\Anaconda3\envs\bank\lib\site-packages\sqlalchemy\orm\session.py", line 3445, in _flush
    flush_context.execute()
  File "C:\ProgramData\Anaconda3\envs\bank\lib\site-packages\sqlalchemy\orm\unitofwork.py", line 456, in execute
    rec.execute(self)
  File "C:\ProgramData\Anaconda3\envs\bank\lib\site-packages\sqlalchemy\orm\unitofwork.py", line 630, in execute
    util.preloaded.orm_persistence.save_obj(
  File "C:\ProgramData\Anaconda3\envs\bank\lib\site-packages\sqlalchemy\orm\persistence.py", line 227, in save_obj
    for table, mapper in base_mapper._sorted_tables.items():
  File "C:\ProgramData\Anaconda3\envs\bank\lib\site-packages\sqlalchemy\util\langhelpers.py", line 1180, in __get__
    obj.__dict__[self.__name__] = result = self.fget(obj)
  File "C:\ProgramData\Anaconda3\envs\bank\lib\site-packages\sqlalchemy\orm\mapper.py", line 3288, in _sorted_tables
    sorted_ = sql_util.sort_tables(
  File "C:\ProgramData\Anaconda3\envs\bank\lib\site-packages\sqlalchemy\sql\ddl.py", line 1208, in sort_tables
    for (t, fkcs) in sort_tables_and_constraints(
  File "C:\ProgramData\Anaconda3\envs\bank\lib\site-packages\sqlalchemy\sql\ddl.py", line 1280, in sort_tables_and_constraints
    filtered = filter_fn(fkc)
  File "C:\ProgramData\Anaconda3\envs\bank\lib\site-packages\sqlalchemy\sql\ddl.py", line 1198, in _skip_fn
    if skip_fn(fk):
  File "C:\ProgramData\Anaconda3\envs\bank\lib\site-packages\sqlalchemy\orm\mapper.py", line 3271, in skip
    dep = table_to_mapper.get(fk.column.table)
  File "C:\ProgramData\Anaconda3\envs\bank\lib\site-packages\sqlalchemy\util\langhelpers.py", line 1113, in __get__
    obj.__dict__[self.__name__] = result = self.fget(obj)
  File "C:\ProgramData\Anaconda3\envs\bank\lib\site-packages\sqlalchemy\sql\schema.py", line 2410, in column
    raise exc.NoReferencedTableError(
sqlalchemy.exc.NoReferencedTableError: Foreign key associated with column 'customer_account.account_id' could not find table 'bankaccount' with which to generate a foreign key to target column 'id'
2022-01-30 21:18:11,062:utility.py:logger_expt:ERROR:Foreign key associated with column 'customer_account.account_id' could not find table 'bankaccount' with which to generate a foreign key to target column 'id'
Traceback (most recent call last):
  File "C:\Users\huang\OneDrive\14-code\bank\database.py", line 90, in new_rec_in_db
    session.commit()
  File "C:\ProgramData\Anaconda3\envs\bank\lib\site-packages\sqlalchemy\orm\session.py", line 1428, in commit
    self._transaction.commit(_to_root=self.future)
  File "C:\ProgramData\Anaconda3\envs\bank\lib\site-packages\sqlalchemy\orm\session.py", line 829, in commit
    self._prepare_impl()
  File "C:\ProgramData\Anaconda3\envs\bank\lib\site-packages\sqlalchemy\orm\session.py", line 808, in _prepare_impl
    self.session.flush()
  File "C:\ProgramData\Anaconda3\envs\bank\lib\site-packages\sqlalchemy\orm\session.py", line 3345, in flush
    self._flush(objects)
  File "C:\ProgramData\Anaconda3\envs\bank\lib\site-packages\sqlalchemy\orm\session.py", line 3485, in _flush
    transaction.rollback(_capture_exception=True)
  File "C:\ProgramData\Anaconda3\envs\bank\lib\site-packages\sqlalchemy\util\langhelpers.py", line 70, in __exit__
    compat.raise_(
  File "C:\ProgramData\Anaconda3\envs\bank\lib\site-packages\sqlalchemy\util\compat.py", line 207, in raise_
    raise exception
  File "C:\ProgramData\Anaconda3\envs\bank\lib\site-packages\sqlalchemy\orm\session.py", line 3445, in _flush
    flush_context.execute()
  File "C:\ProgramData\Anaconda3\envs\bank\lib\site-packages\sqlalchemy\orm\unitofwork.py", line 456, in execute
    rec.execute(self)
  File "C:\ProgramData\Anaconda3\envs\bank\lib\site-packages\sqlalchemy\orm\unitofwork.py", line 630, in execute
    util.preloaded.orm_persistence.save_obj(
  File "C:\ProgramData\Anaconda3\envs\bank\lib\site-packages\sqlalchemy\orm\persistence.py", line 227, in save_obj
    for table, mapper in base_mapper._sorted_tables.items():
  File "C:\ProgramData\Anaconda3\envs\bank\lib\site-packages\sqlalchemy\util\langhelpers.py", line 1180, in __get__
    obj.__dict__[self.__name__] = result = self.fget(obj)
  File "C:\ProgramData\Anaconda3\envs\bank\lib\site-packages\sqlalchemy\orm\mapper.py", line 3288, in _sorted_tables
    sorted_ = sql_util.sort_tables(
  File "C:\ProgramData\Anaconda3\envs\bank\lib\site-packages\sqlalchemy\sql\ddl.py", line 1208, in sort_tables
    for (t, fkcs) in sort_tables_and_constraints(
  File "C:\ProgramData\Anaconda3\envs\bank\lib\site-packages\sqlalchemy\sql\ddl.py", line 1280, in sort_tables_and_constraints
    filtered = filter_fn(fkc)
  File "C:\ProgramData\Anaconda3\envs\bank\lib\site-packages\sqlalchemy\sql\ddl.py", line 1198, in _skip_fn
    if skip_fn(fk):
  File "C:\ProgramData\Anaconda3\envs\bank\lib\site-packages\sqlalchemy\orm\mapper.py", line 3271, in skip
    dep = table_to_mapper.get(fk.column.table)
  File "C:\ProgramData\Anaconda3\envs\bank\lib\site-packages\sqlalchemy\util\langhelpers.py", line 1113, in __get__
    obj.__dict__[self.__name__] = result = self.fget(obj)
  File "C:\ProgramData\Anaconda3\envs\bank\lib\site-packages\sqlalchemy\sql\schema.py", line 2410, in column
    raise exc.NoReferencedTableError(
sqlalchemy.exc.NoReferencedTableError: Foreign key associated with column 'customer_account.account_id' could not find table 'bankaccount' with which to generate a foreign key to target column 'id'
2022-01-30 21:31:57,384:utility.py:logger_expt:ERROR:Foreign key associated with column 'customer_account.account_id' could not find table 'bankaccount' with which to generate a foreign key to target column 'id'
Traceback (most recent call last):
  File "C:\Users\huang\OneDrive\14-code\bank\database.py", line 90, in new_rec_in_db
    session.commit()
  File "C:\ProgramData\Anaconda3\envs\bank\lib\site-packages\sqlalchemy\orm\session.py", line 1428, in commit
    self._transaction.commit(_to_root=self.future)
  File "C:\ProgramData\Anaconda3\envs\bank\lib\site-packages\sqlalchemy\orm\session.py", line 829, in commit
    self._prepare_impl()
  File "C:\ProgramData\Anaconda3\envs\bank\lib\site-packages\sqlalchemy\orm\session.py", line 808, in _prepare_impl
    self.session.flush()
  File "C:\ProgramData\Anaconda3\envs\bank\lib\site-packages\sqlalchemy\orm\session.py", line 3345, in flush
    self._flush(objects)
  File "C:\ProgramData\Anaconda3\envs\bank\lib\site-packages\sqlalchemy\orm\session.py", line 3485, in _flush
    transaction.rollback(_capture_exception=True)
  File "C:\ProgramData\Anaconda3\envs\bank\lib\site-packages\sqlalchemy\util\langhelpers.py", line 70, in __exit__
    compat.raise_(
  File "C:\ProgramData\Anaconda3\envs\bank\lib\site-packages\sqlalchemy\util\compat.py", line 207, in raise_
    raise exception
  File "C:\ProgramData\Anaconda3\envs\bank\lib\site-packages\sqlalchemy\orm\session.py", line 3445, in _flush
    flush_context.execute()
  File "C:\ProgramData\Anaconda3\envs\bank\lib\site-packages\sqlalchemy\orm\unitofwork.py", line 456, in execute
    rec.execute(self)
  File "C:\ProgramData\Anaconda3\envs\bank\lib\site-packages\sqlalchemy\orm\unitofwork.py", line 630, in execute
    util.preloaded.orm_persistence.save_obj(
  File "C:\ProgramData\Anaconda3\envs\bank\lib\site-packages\sqlalchemy\orm\persistence.py", line 227, in save_obj
    for table, mapper in base_mapper._sorted_tables.items():
  File "C:\ProgramData\Anaconda3\envs\bank\lib\site-packages\sqlalchemy\util\langhelpers.py", line 1180, in __get__
    obj.__dict__[self.__name__] = result = self.fget(obj)
  File "C:\ProgramData\Anaconda3\envs\bank\lib\site-packages\sqlalchemy\orm\mapper.py", line 3288, in _sorted_tables
    sorted_ = sql_util.sort_tables(
  File "C:\ProgramData\Anaconda3\envs\bank\lib\site-packages\sqlalchemy\sql\ddl.py", line 1208, in sort_tables
    for (t, fkcs) in sort_tables_and_constraints(
  File "C:\ProgramData\Anaconda3\envs\bank\lib\site-packages\sqlalchemy\sql\ddl.py", line 1280, in sort_tables_and_constraints
    filtered = filter_fn(fkc)
  File "C:\ProgramData\Anaconda3\envs\bank\lib\site-packages\sqlalchemy\sql\ddl.py", line 1198, in _skip_fn
    if skip_fn(fk):
  File "C:\ProgramData\Anaconda3\envs\bank\lib\site-packages\sqlalchemy\orm\mapper.py", line 3271, in skip
    dep = table_to_mapper.get(fk.column.table)
  File "C:\ProgramData\Anaconda3\envs\bank\lib\site-packages\sqlalchemy\util\langhelpers.py", line 1113, in __get__
    obj.__dict__[self.__name__] = result = self.fget(obj)
  File "C:\ProgramData\Anaconda3\envs\bank\lib\site-packages\sqlalchemy\sql\schema.py", line 2410, in column
    raise exc.NoReferencedTableError(
sqlalchemy.exc.NoReferencedTableError: Foreign key associated with column 'customer_account.account_id' could not find table 'bankaccount' with which to generate a foreign key to target column 'id'
2022-01-30 21:33:34,982:utility.py:logger_expt:ERROR:Foreign key associated with column 'customer_account.customer_id' could not find table 'customer' with which to generate a foreign key to target column 'id'
Traceback (most recent call last):
  File "C:\Users\huang\OneDrive\14-code\bank\database.py", line 90, in new_rec_in_db
    session.commit()
  File "C:\ProgramData\Anaconda3\envs\bank\lib\site-packages\sqlalchemy\orm\session.py", line 1428, in commit
    self._transaction.commit(_to_root=self.future)
  File "C:\ProgramData\Anaconda3\envs\bank\lib\site-packages\sqlalchemy\orm\session.py", line 829, in commit
    self._prepare_impl()
  File "C:\ProgramData\Anaconda3\envs\bank\lib\site-packages\sqlalchemy\orm\session.py", line 808, in _prepare_impl
    self.session.flush()
  File "C:\ProgramData\Anaconda3\envs\bank\lib\site-packages\sqlalchemy\orm\session.py", line 3345, in flush
    self._flush(objects)
  File "C:\ProgramData\Anaconda3\envs\bank\lib\site-packages\sqlalchemy\orm\session.py", line 3485, in _flush
    transaction.rollback(_capture_exception=True)
  File "C:\ProgramData\Anaconda3\envs\bank\lib\site-packages\sqlalchemy\util\langhelpers.py", line 70, in __exit__
    compat.raise_(
  File "C:\ProgramData\Anaconda3\envs\bank\lib\site-packages\sqlalchemy\util\compat.py", line 207, in raise_
    raise exception
  File "C:\ProgramData\Anaconda3\envs\bank\lib\site-packages\sqlalchemy\orm\session.py", line 3445, in _flush
    flush_context.execute()
  File "C:\ProgramData\Anaconda3\envs\bank\lib\site-packages\sqlalchemy\orm\unitofwork.py", line 456, in execute
    rec.execute(self)
  File "C:\ProgramData\Anaconda3\envs\bank\lib\site-packages\sqlalchemy\orm\unitofwork.py", line 630, in execute
    util.preloaded.orm_persistence.save_obj(
  File "C:\ProgramData\Anaconda3\envs\bank\lib\site-packages\sqlalchemy\orm\persistence.py", line 227, in save_obj
    for table, mapper in base_mapper._sorted_tables.items():
  File "C:\ProgramData\Anaconda3\envs\bank\lib\site-packages\sqlalchemy\util\langhelpers.py", line 1180, in __get__
    obj.__dict__[self.__name__] = result = self.fget(obj)
  File "C:\ProgramData\Anaconda3\envs\bank\lib\site-packages\sqlalchemy\orm\mapper.py", line 3288, in _sorted_tables
    sorted_ = sql_util.sort_tables(
  File "C:\ProgramData\Anaconda3\envs\bank\lib\site-packages\sqlalchemy\sql\ddl.py", line 1208, in sort_tables
    for (t, fkcs) in sort_tables_and_constraints(
  File "C:\ProgramData\Anaconda3\envs\bank\lib\site-packages\sqlalchemy\sql\ddl.py", line 1280, in sort_tables_and_constraints
    filtered = filter_fn(fkc)
  File "C:\ProgramData\Anaconda3\envs\bank\lib\site-packages\sqlalchemy\sql\ddl.py", line 1198, in _skip_fn
    if skip_fn(fk):
  File "C:\ProgramData\Anaconda3\envs\bank\lib\site-packages\sqlalchemy\orm\mapper.py", line 3271, in skip
    dep = table_to_mapper.get(fk.column.table)
  File "C:\ProgramData\Anaconda3\envs\bank\lib\site-packages\sqlalchemy\util\langhelpers.py", line 1113, in __get__
    obj.__dict__[self.__name__] = result = self.fget(obj)
  File "C:\ProgramData\Anaconda3\envs\bank\lib\site-packages\sqlalchemy\sql\schema.py", line 2410, in column
    raise exc.NoReferencedTableError(
sqlalchemy.exc.NoReferencedTableError: Foreign key associated with column 'customer_account.customer_id' could not find table 'customer' with which to generate a foreign key to target column 'id'
2022-01-30 21:53:25,091:utility.py:logger_expt:ERROR:(pymysql.err.ProgrammingError) (1146, "Table 'bank.ass_customer_account' doesn't exist")
[SQL: INSERT INTO ass_customer_account (customer_id, account_id, cr_datetime) VALUES (%(customer_id)s, %(account_id)s, %(cr_datetime)s)]
[parameters: {'customer_id': 100, 'account_id': 175, 'cr_datetime': datetime.datetime(2022, 1, 30, 21, 53, 25, 76602)}]
(Background on this error at: https://sqlalche.me/e/14/f405)
Traceback (most recent call last):
  File "C:\ProgramData\Anaconda3\envs\bank\lib\site-packages\sqlalchemy\engine\base.py", line 1802, in _execute_context
    self.dialect.do_execute(
  File "C:\ProgramData\Anaconda3\envs\bank\lib\site-packages\sqlalchemy\engine\default.py", line 719, in do_execute
    cursor.execute(statement, parameters)
  File "C:\ProgramData\Anaconda3\envs\bank\lib\site-packages\pymysql\cursors.py", line 148, in execute
    result = self._query(query)
  File "C:\ProgramData\Anaconda3\envs\bank\lib\site-packages\pymysql\cursors.py", line 310, in _query
    conn.query(q)
  File "C:\ProgramData\Anaconda3\envs\bank\lib\site-packages\pymysql\connections.py", line 548, in query
    self._affected_rows = self._read_query_result(unbuffered=unbuffered)
  File "C:\ProgramData\Anaconda3\envs\bank\lib\site-packages\pymysql\connections.py", line 775, in _read_query_result
    result.read()
  File "C:\ProgramData\Anaconda3\envs\bank\lib\site-packages\pymysql\connections.py", line 1156, in read
    first_packet = self.connection._read_packet()
  File "C:\ProgramData\Anaconda3\envs\bank\lib\site-packages\pymysql\connections.py", line 725, in _read_packet
    packet.raise_for_error()
  File "C:\ProgramData\Anaconda3\envs\bank\lib\site-packages\pymysql\protocol.py", line 221, in raise_for_error
    err.raise_mysql_exception(self._data)
  File "C:\ProgramData\Anaconda3\envs\bank\lib\site-packages\pymysql\err.py", line 143, in raise_mysql_exception
    raise errorclass(errno, errval)
pymysql.err.ProgrammingError: (1146, "Table 'bank.ass_customer_account' doesn't exist")

The above exception was the direct cause of the following exception:

Traceback (most recent call last):
  File "C:\Users\huang\OneDrive\14-code\bank\database.py", line 90, in new_rec_in_db
    session.commit()
  File "C:\ProgramData\Anaconda3\envs\bank\lib\site-packages\sqlalchemy\orm\session.py", line 1428, in commit
    self._transaction.commit(_to_root=self.future)
  File "C:\ProgramData\Anaconda3\envs\bank\lib\site-packages\sqlalchemy\orm\session.py", line 829, in commit
    self._prepare_impl()
  File "C:\ProgramData\Anaconda3\envs\bank\lib\site-packages\sqlalchemy\orm\session.py", line 808, in _prepare_impl
    self.session.flush()
  File "C:\ProgramData\Anaconda3\envs\bank\lib\site-packages\sqlalchemy\orm\session.py", line 3345, in flush
    self._flush(objects)
  File "C:\ProgramData\Anaconda3\envs\bank\lib\site-packages\sqlalchemy\orm\session.py", line 3485, in _flush
    transaction.rollback(_capture_exception=True)
  File "C:\ProgramData\Anaconda3\envs\bank\lib\site-packages\sqlalchemy\util\langhelpers.py", line 70, in __exit__
    compat.raise_(
  File "C:\ProgramData\Anaconda3\envs\bank\lib\site-packages\sqlalchemy\util\compat.py", line 207, in raise_
    raise exception
  File "C:\ProgramData\Anaconda3\envs\bank\lib\site-packages\sqlalchemy\orm\session.py", line 3445, in _flush
    flush_context.execute()
  File "C:\ProgramData\Anaconda3\envs\bank\lib\site-packages\sqlalchemy\orm\unitofwork.py", line 456, in execute
    rec.execute(self)
  File "C:\ProgramData\Anaconda3\envs\bank\lib\site-packages\sqlalchemy\orm\unitofwork.py", line 630, in execute
    util.preloaded.orm_persistence.save_obj(
  File "C:\ProgramData\Anaconda3\envs\bank\lib\site-packages\sqlalchemy\orm\persistence.py", line 244, in save_obj
    _emit_insert_statements(
  File "C:\ProgramData\Anaconda3\envs\bank\lib\site-packages\sqlalchemy\orm\persistence.py", line 1221, in _emit_insert_statements
    result = connection._execute_20(
  File "C:\ProgramData\Anaconda3\envs\bank\lib\site-packages\sqlalchemy\engine\base.py", line 1614, in _execute_20
    return meth(self, args_10style, kwargs_10style, execution_options)
  File "C:\ProgramData\Anaconda3\envs\bank\lib\site-packages\sqlalchemy\sql\elements.py", line 325, in _execute_on_connection
    return connection._execute_clauseelement(
  File "C:\ProgramData\Anaconda3\envs\bank\lib\site-packages\sqlalchemy\engine\base.py", line 1481, in _execute_clauseelement
    ret = self._execute_context(
  File "C:\ProgramData\Anaconda3\envs\bank\lib\site-packages\sqlalchemy\engine\base.py", line 1845, in _execute_context
    self._handle_dbapi_exception(
  File "C:\ProgramData\Anaconda3\envs\bank\lib\site-packages\sqlalchemy\engine\base.py", line 2026, in _handle_dbapi_exception
    util.raise_(
  File "C:\ProgramData\Anaconda3\envs\bank\lib\site-packages\sqlalchemy\util\compat.py", line 207, in raise_
    raise exception
  File "C:\ProgramData\Anaconda3\envs\bank\lib\site-packages\sqlalchemy\engine\base.py", line 1802, in _execute_context
    self.dialect.do_execute(
  File "C:\ProgramData\Anaconda3\envs\bank\lib\site-packages\sqlalchemy\engine\default.py", line 719, in do_execute
    cursor.execute(statement, parameters)
  File "C:\ProgramData\Anaconda3\envs\bank\lib\site-packages\pymysql\cursors.py", line 148, in execute
    result = self._query(query)
  File "C:\ProgramData\Anaconda3\envs\bank\lib\site-packages\pymysql\cursors.py", line 310, in _query
    conn.query(q)
  File "C:\ProgramData\Anaconda3\envs\bank\lib\site-packages\pymysql\connections.py", line 548, in query
    self._affected_rows = self._read_query_result(unbuffered=unbuffered)
  File "C:\ProgramData\Anaconda3\envs\bank\lib\site-packages\pymysql\connections.py", line 775, in _read_query_result
    result.read()
  File "C:\ProgramData\Anaconda3\envs\bank\lib\site-packages\pymysql\connections.py", line 1156, in read
    first_packet = self.connection._read_packet()
  File "C:\ProgramData\Anaconda3\envs\bank\lib\site-packages\pymysql\connections.py", line 725, in _read_packet
    packet.raise_for_error()
  File "C:\ProgramData\Anaconda3\envs\bank\lib\site-packages\pymysql\protocol.py", line 221, in raise_for_error
    err.raise_mysql_exception(self._data)
  File "C:\ProgramData\Anaconda3\envs\bank\lib\site-packages\pymysql\err.py", line 143, in raise_mysql_exception
    raise errorclass(errno, errval)
sqlalchemy.exc.ProgrammingError: (pymysql.err.ProgrammingError) (1146, "Table 'bank.ass_customer_account' doesn't exist")
[SQL: INSERT INTO ass_customer_account (customer_id, account_id, cr_datetime) VALUES (%(customer_id)s, %(account_id)s, %(cr_datetime)s)]
[parameters: {'customer_id': 100, 'account_id': 175, 'cr_datetime': datetime.datetime(2022, 1, 30, 21, 53, 25, 76602)}]
(Background on this error at: https://sqlalche.me/e/14/f405)
2022-01-30 21:55:31,504:utility.py:logger_expt:ERROR:(pymysql.err.ProgrammingError) (1146, "Table 'bank.ass_customer_account' doesn't exist")
[SQL: INSERT INTO ass_customer_account (customer_id, account_id, cr_datetime) VALUES (%(customer_id)s, %(account_id)s, %(cr_datetime)s)]
[parameters: {'customer_id': 101, 'account_id': 104, 'cr_datetime': datetime.datetime(2022, 1, 30, 21, 55, 31, 497937)}]
(Background on this error at: https://sqlalche.me/e/14/f405)
Traceback (most recent call last):
  File "C:\ProgramData\Anaconda3\envs\bank\lib\site-packages\sqlalchemy\engine\base.py", line 1802, in _execute_context
    self.dialect.do_execute(
  File "C:\ProgramData\Anaconda3\envs\bank\lib\site-packages\sqlalchemy\engine\default.py", line 719, in do_execute
    cursor.execute(statement, parameters)
  File "C:\ProgramData\Anaconda3\envs\bank\lib\site-packages\pymysql\cursors.py", line 148, in execute
    result = self._query(query)
  File "C:\ProgramData\Anaconda3\envs\bank\lib\site-packages\pymysql\cursors.py", line 310, in _query
    conn.query(q)
  File "C:\ProgramData\Anaconda3\envs\bank\lib\site-packages\pymysql\connections.py", line 548, in query
    self._affected_rows = self._read_query_result(unbuffered=unbuffered)
  File "C:\ProgramData\Anaconda3\envs\bank\lib\site-packages\pymysql\connections.py", line 775, in _read_query_result
    result.read()
  File "C:\ProgramData\Anaconda3\envs\bank\lib\site-packages\pymysql\connections.py", line 1156, in read
    first_packet = self.connection._read_packet()
  File "C:\ProgramData\Anaconda3\envs\bank\lib\site-packages\pymysql\connections.py", line 725, in _read_packet
    packet.raise_for_error()
  File "C:\ProgramData\Anaconda3\envs\bank\lib\site-packages\pymysql\protocol.py", line 221, in raise_for_error
    err.raise_mysql_exception(self._data)
  File "C:\ProgramData\Anaconda3\envs\bank\lib\site-packages\pymysql\err.py", line 143, in raise_mysql_exception
    raise errorclass(errno, errval)
pymysql.err.ProgrammingError: (1146, "Table 'bank.ass_customer_account' doesn't exist")

The above exception was the direct cause of the following exception:

Traceback (most recent call last):
  File "C:\Users\huang\OneDrive\14-code\bank\database.py", line 90, in new_rec_in_db
    session.commit()
  File "C:\ProgramData\Anaconda3\envs\bank\lib\site-packages\sqlalchemy\orm\session.py", line 1428, in commit
    self._transaction.commit(_to_root=self.future)
  File "C:\ProgramData\Anaconda3\envs\bank\lib\site-packages\sqlalchemy\orm\session.py", line 829, in commit
    self._prepare_impl()
  File "C:\ProgramData\Anaconda3\envs\bank\lib\site-packages\sqlalchemy\orm\session.py", line 808, in _prepare_impl
    self.session.flush()
  File "C:\ProgramData\Anaconda3\envs\bank\lib\site-packages\sqlalchemy\orm\session.py", line 3345, in flush
    self._flush(objects)
  File "C:\ProgramData\Anaconda3\envs\bank\lib\site-packages\sqlalchemy\orm\session.py", line 3485, in _flush
    transaction.rollback(_capture_exception=True)
  File "C:\ProgramData\Anaconda3\envs\bank\lib\site-packages\sqlalchemy\util\langhelpers.py", line 70, in __exit__
    compat.raise_(
  File "C:\ProgramData\Anaconda3\envs\bank\lib\site-packages\sqlalchemy\util\compat.py", line 207, in raise_
    raise exception
  File "C:\ProgramData\Anaconda3\envs\bank\lib\site-packages\sqlalchemy\orm\session.py", line 3445, in _flush
    flush_context.execute()
  File "C:\ProgramData\Anaconda3\envs\bank\lib\site-packages\sqlalchemy\orm\unitofwork.py", line 456, in execute
    rec.execute(self)
  File "C:\ProgramData\Anaconda3\envs\bank\lib\site-packages\sqlalchemy\orm\unitofwork.py", line 630, in execute
    util.preloaded.orm_persistence.save_obj(
  File "C:\ProgramData\Anaconda3\envs\bank\lib\site-packages\sqlalchemy\orm\persistence.py", line 244, in save_obj
    _emit_insert_statements(
  File "C:\ProgramData\Anaconda3\envs\bank\lib\site-packages\sqlalchemy\orm\persistence.py", line 1221, in _emit_insert_statements
    result = connection._execute_20(
  File "C:\ProgramData\Anaconda3\envs\bank\lib\site-packages\sqlalchemy\engine\base.py", line 1614, in _execute_20
    return meth(self, args_10style, kwargs_10style, execution_options)
  File "C:\ProgramData\Anaconda3\envs\bank\lib\site-packages\sqlalchemy\sql\elements.py", line 325, in _execute_on_connection
    return connection._execute_clauseelement(
  File "C:\ProgramData\Anaconda3\envs\bank\lib\site-packages\sqlalchemy\engine\base.py", line 1481, in _execute_clauseelement
    ret = self._execute_context(
  File "C:\ProgramData\Anaconda3\envs\bank\lib\site-packages\sqlalchemy\engine\base.py", line 1845, in _execute_context
    self._handle_dbapi_exception(
  File "C:\ProgramData\Anaconda3\envs\bank\lib\site-packages\sqlalchemy\engine\base.py", line 2026, in _handle_dbapi_exception
    util.raise_(
  File "C:\ProgramData\Anaconda3\envs\bank\lib\site-packages\sqlalchemy\util\compat.py", line 207, in raise_
    raise exception
  File "C:\ProgramData\Anaconda3\envs\bank\lib\site-packages\sqlalchemy\engine\base.py", line 1802, in _execute_context
    self.dialect.do_execute(
  File "C:\ProgramData\Anaconda3\envs\bank\lib\site-packages\sqlalchemy\engine\default.py", line 719, in do_execute
    cursor.execute(statement, parameters)
  File "C:\ProgramData\Anaconda3\envs\bank\lib\site-packages\pymysql\cursors.py", line 148, in execute
    result = self._query(query)
  File "C:\ProgramData\Anaconda3\envs\bank\lib\site-packages\pymysql\cursors.py", line 310, in _query
    conn.query(q)
  File "C:\ProgramData\Anaconda3\envs\bank\lib\site-packages\pymysql\connections.py", line 548, in query
    self._affected_rows = self._read_query_result(unbuffered=unbuffered)
  File "C:\ProgramData\Anaconda3\envs\bank\lib\site-packages\pymysql\connections.py", line 775, in _read_query_result
    result.read()
  File "C:\ProgramData\Anaconda3\envs\bank\lib\site-packages\pymysql\connections.py", line 1156, in read
    first_packet = self.connection._read_packet()
  File "C:\ProgramData\Anaconda3\envs\bank\lib\site-packages\pymysql\connections.py", line 725, in _read_packet
    packet.raise_for_error()
  File "C:\ProgramData\Anaconda3\envs\bank\lib\site-packages\pymysql\protocol.py", line 221, in raise_for_error
    err.raise_mysql_exception(self._data)
  File "C:\ProgramData\Anaconda3\envs\bank\lib\site-packages\pymysql\err.py", line 143, in raise_mysql_exception
    raise errorclass(errno, errval)
sqlalchemy.exc.ProgrammingError: (pymysql.err.ProgrammingError) (1146, "Table 'bank.ass_customer_account' doesn't exist")
[SQL: INSERT INTO ass_customer_account (customer_id, account_id, cr_datetime) VALUES (%(customer_id)s, %(account_id)s, %(cr_datetime)s)]
[parameters: {'customer_id': 101, 'account_id': 104, 'cr_datetime': datetime.datetime(2022, 1, 30, 21, 55, 31, 497937)}]
(Background on this error at: https://sqlalche.me/e/14/f405)
2022-01-31 08:22:22,128:utility.py:logger_app:INFO:hello!
2022-01-31 08:22:43,560:utility.py:logger_app:INFO:hello!
2022-02-01 16:24:14,389:utility.py:logger_expt:ERROR:(pymysql.err.DataError) (1366, "Incorrect integer value: 'c' for column 'balance' at row 1")
[SQL: INSERT INTO bankaccount (account_no, account_type, balance, intrst_rate, cr_date) VALUES (%(account_no)s, %(account_type)s, %(balance)s, %(intrst_rate)s, %(cr_date)s)]
[parameters: {'account_no': None, 'account_type': 'savings', 'balance': 'c', 'intrst_rate': 400, 'cr_date': datetime.datetime(2022, 2, 1, 16, 24, 14, 112039)}]
(Background on this error at: https://sqlalche.me/e/14/9h9h)
Traceback (most recent call last):
  File "C:\ProgramData\Anaconda3\envs\bank\lib\site-packages\sqlalchemy\engine\base.py", line 1802, in _execute_context
    self.dialect.do_execute(
  File "C:\ProgramData\Anaconda3\envs\bank\lib\site-packages\sqlalchemy\engine\default.py", line 719, in do_execute
    cursor.execute(statement, parameters)
  File "C:\ProgramData\Anaconda3\envs\bank\lib\site-packages\pymysql\cursors.py", line 148, in execute
    result = self._query(query)
  File "C:\ProgramData\Anaconda3\envs\bank\lib\site-packages\pymysql\cursors.py", line 310, in _query
    conn.query(q)
  File "C:\ProgramData\Anaconda3\envs\bank\lib\site-packages\pymysql\connections.py", line 548, in query
    self._affected_rows = self._read_query_result(unbuffered=unbuffered)
  File "C:\ProgramData\Anaconda3\envs\bank\lib\site-packages\pymysql\connections.py", line 775, in _read_query_result
    result.read()
  File "C:\ProgramData\Anaconda3\envs\bank\lib\site-packages\pymysql\connections.py", line 1156, in read
    first_packet = self.connection._read_packet()
  File "C:\ProgramData\Anaconda3\envs\bank\lib\site-packages\pymysql\connections.py", line 725, in _read_packet
    packet.raise_for_error()
  File "C:\ProgramData\Anaconda3\envs\bank\lib\site-packages\pymysql\protocol.py", line 221, in raise_for_error
    err.raise_mysql_exception(self._data)
  File "C:\ProgramData\Anaconda3\envs\bank\lib\site-packages\pymysql\err.py", line 143, in raise_mysql_exception
    raise errorclass(errno, errval)
pymysql.err.DataError: (1366, "Incorrect integer value: 'c' for column 'balance' at row 1")

The above exception was the direct cause of the following exception:

Traceback (most recent call last):
  File "C:\Users\huang\OneDrive\14-code\bank\database.py", line 90, in new_rec_in_db
    session.commit()
  File "C:\ProgramData\Anaconda3\envs\bank\lib\site-packages\sqlalchemy\orm\session.py", line 1428, in commit
    self._transaction.commit(_to_root=self.future)
  File "C:\ProgramData\Anaconda3\envs\bank\lib\site-packages\sqlalchemy\orm\session.py", line 829, in commit
    self._prepare_impl()
  File "C:\ProgramData\Anaconda3\envs\bank\lib\site-packages\sqlalchemy\orm\session.py", line 808, in _prepare_impl
    self.session.flush()
  File "C:\ProgramData\Anaconda3\envs\bank\lib\site-packages\sqlalchemy\orm\session.py", line 3345, in flush
    self._flush(objects)
  File "C:\ProgramData\Anaconda3\envs\bank\lib\site-packages\sqlalchemy\orm\session.py", line 3485, in _flush
    transaction.rollback(_capture_exception=True)
  File "C:\ProgramData\Anaconda3\envs\bank\lib\site-packages\sqlalchemy\util\langhelpers.py", line 70, in __exit__
    compat.raise_(
  File "C:\ProgramData\Anaconda3\envs\bank\lib\site-packages\sqlalchemy\util\compat.py", line 207, in raise_
    raise exception
  File "C:\ProgramData\Anaconda3\envs\bank\lib\site-packages\sqlalchemy\orm\session.py", line 3445, in _flush
    flush_context.execute()
  File "C:\ProgramData\Anaconda3\envs\bank\lib\site-packages\sqlalchemy\orm\unitofwork.py", line 456, in execute
    rec.execute(self)
  File "C:\ProgramData\Anaconda3\envs\bank\lib\site-packages\sqlalchemy\orm\unitofwork.py", line 630, in execute
    util.preloaded.orm_persistence.save_obj(
  File "C:\ProgramData\Anaconda3\envs\bank\lib\site-packages\sqlalchemy\orm\persistence.py", line 244, in save_obj
    _emit_insert_statements(
  File "C:\ProgramData\Anaconda3\envs\bank\lib\site-packages\sqlalchemy\orm\persistence.py", line 1221, in _emit_insert_statements
    result = connection._execute_20(
  File "C:\ProgramData\Anaconda3\envs\bank\lib\site-packages\sqlalchemy\engine\base.py", line 1614, in _execute_20
    return meth(self, args_10style, kwargs_10style, execution_options)
  File "C:\ProgramData\Anaconda3\envs\bank\lib\site-packages\sqlalchemy\sql\elements.py", line 325, in _execute_on_connection
    return connection._execute_clauseelement(
  File "C:\ProgramData\Anaconda3\envs\bank\lib\site-packages\sqlalchemy\engine\base.py", line 1481, in _execute_clauseelement
    ret = self._execute_context(
  File "C:\ProgramData\Anaconda3\envs\bank\lib\site-packages\sqlalchemy\engine\base.py", line 1845, in _execute_context
    self._handle_dbapi_exception(
  File "C:\ProgramData\Anaconda3\envs\bank\lib\site-packages\sqlalchemy\engine\base.py", line 2026, in _handle_dbapi_exception
    util.raise_(
  File "C:\ProgramData\Anaconda3\envs\bank\lib\site-packages\sqlalchemy\util\compat.py", line 207, in raise_
    raise exception
  File "C:\ProgramData\Anaconda3\envs\bank\lib\site-packages\sqlalchemy\engine\base.py", line 1802, in _execute_context
    self.dialect.do_execute(
  File "C:\ProgramData\Anaconda3\envs\bank\lib\site-packages\sqlalchemy\engine\default.py", line 719, in do_execute
    cursor.execute(statement, parameters)
  File "C:\ProgramData\Anaconda3\envs\bank\lib\site-packages\pymysql\cursors.py", line 148, in execute
    result = self._query(query)
  File "C:\ProgramData\Anaconda3\envs\bank\lib\site-packages\pymysql\cursors.py", line 310, in _query
    conn.query(q)
  File "C:\ProgramData\Anaconda3\envs\bank\lib\site-packages\pymysql\connections.py", line 548, in query
    self._affected_rows = self._read_query_result(unbuffered=unbuffered)
  File "C:\ProgramData\Anaconda3\envs\bank\lib\site-packages\pymysql\connections.py", line 775, in _read_query_result
    result.read()
  File "C:\ProgramData\Anaconda3\envs\bank\lib\site-packages\pymysql\connections.py", line 1156, in read
    first_packet = self.connection._read_packet()
  File "C:\ProgramData\Anaconda3\envs\bank\lib\site-packages\pymysql\connections.py", line 725, in _read_packet
    packet.raise_for_error()
  File "C:\ProgramData\Anaconda3\envs\bank\lib\site-packages\pymysql\protocol.py", line 221, in raise_for_error
    err.raise_mysql_exception(self._data)
  File "C:\ProgramData\Anaconda3\envs\bank\lib\site-packages\pymysql\err.py", line 143, in raise_mysql_exception
    raise errorclass(errno, errval)
sqlalchemy.exc.DataError: (pymysql.err.DataError) (1366, "Incorrect integer value: 'c' for column 'balance' at row 1")
[SQL: INSERT INTO bankaccount (account_no, account_type, balance, intrst_rate, cr_date) VALUES (%(account_no)s, %(account_type)s, %(balance)s, %(intrst_rate)s, %(cr_date)s)]
[parameters: {'account_no': None, 'account_type': 'savings', 'balance': 'c', 'intrst_rate': 400, 'cr_date': datetime.datetime(2022, 2, 1, 16, 24, 14, 112039)}]
(Background on this error at: https://sqlalche.me/e/14/9h9h)
2022-02-01 21:10:22,405:utility.py:logger_expt:ERROR:'Query' object has no attribute 'filteryBy'
Traceback (most recent call last):
  File "C:/Users/huang/OneDrive/14-code/bank/bankaccount.py", line 93, in get_max_account_no
    max_no = session.query(func.max(BankAccount.account_no)).filteryBy(BankAccount.account_type=='checking')
AttributeError: 'Query' object has no attribute 'filteryBy'
2022-02-01 21:10:46,562:utility.py:logger_expt:ERROR:'Query' object has no attribute 'filteryBy'
Traceback (most recent call last):
  File "C:/Users/huang/OneDrive/14-code/bank/bankaccount.py", line 93, in get_max_account_no
    max_no = session.query(func.max(BankAccount.account_no)).filteryBy(BankAccount.account_type=='savings')
AttributeError: 'Query' object has no attribute 'filteryBy'
2022-02-01 21:19:08,420:utility.py:logger_expt:ERROR:'Query' object has no attribute 'filteryBy'
Traceback (most recent call last):
  File "C:/Users/huang/OneDrive/14-code/bank/bankaccount.py", line 93, in get_max_account_no
    max_no = session.query(func.max(BankAccount.account_no)).filteryBy(BankAccount.account_no<30000).scalar()
AttributeError: 'Query' object has no attribute 'filteryBy'
2022-02-01 21:22:06,004:utility.py:logger_expt:ERROR:'>' not supported between instances of 'DeclarativeMeta' and 'int'
Traceback (most recent call last):
  File "C:/Users/huang/OneDrive/14-code/bank/bankaccount.py", line 93, in get_max_account_no
    max_no = session.query(func.max(BankAccount.account_no)).filter(BankAccount>20000).scalar()
TypeError: '>' not supported between instances of 'DeclarativeMeta' and 'int'
2022-02-02 06:50:45,388:utility.py:logger_expt:ERROR:(pymysql.err.IntegrityError) (1062, "Duplicate entry '1' for key 'sequence.PRIMARY'")
[SQL: INSERT INTO sequence (id) VALUES (%(id)s)]
[parameters: {'id': 1}]
(Background on this error at: https://sqlalche.me/e/14/gkpj)
Traceback (most recent call last):
  File "C:\ProgramData\Anaconda3\envs\bank\lib\site-packages\sqlalchemy\engine\base.py", line 1802, in _execute_context
    self.dialect.do_execute(
  File "C:\ProgramData\Anaconda3\envs\bank\lib\site-packages\sqlalchemy\engine\default.py", line 719, in do_execute
    cursor.execute(statement, parameters)
  File "C:\ProgramData\Anaconda3\envs\bank\lib\site-packages\pymysql\cursors.py", line 148, in execute
    result = self._query(query)
  File "C:\ProgramData\Anaconda3\envs\bank\lib\site-packages\pymysql\cursors.py", line 310, in _query
    conn.query(q)
  File "C:\ProgramData\Anaconda3\envs\bank\lib\site-packages\pymysql\connections.py", line 548, in query
    self._affected_rows = self._read_query_result(unbuffered=unbuffered)
  File "C:\ProgramData\Anaconda3\envs\bank\lib\site-packages\pymysql\connections.py", line 775, in _read_query_result
    result.read()
  File "C:\ProgramData\Anaconda3\envs\bank\lib\site-packages\pymysql\connections.py", line 1156, in read
    first_packet = self.connection._read_packet()
  File "C:\ProgramData\Anaconda3\envs\bank\lib\site-packages\pymysql\connections.py", line 725, in _read_packet
    packet.raise_for_error()
  File "C:\ProgramData\Anaconda3\envs\bank\lib\site-packages\pymysql\protocol.py", line 221, in raise_for_error
    err.raise_mysql_exception(self._data)
  File "C:\ProgramData\Anaconda3\envs\bank\lib\site-packages\pymysql\err.py", line 143, in raise_mysql_exception
    raise errorclass(errno, errval)
pymysql.err.IntegrityError: (1062, "Duplicate entry '1' for key 'sequence.PRIMARY'")

The above exception was the direct cause of the following exception:

Traceback (most recent call last):
  File "C:\Users\huang\OneDrive\14-code\bank\database.py", line 90, in new_rec_in_db
    session.commit()
  File "C:\ProgramData\Anaconda3\envs\bank\lib\site-packages\sqlalchemy\orm\session.py", line 1428, in commit
    self._transaction.commit(_to_root=self.future)
  File "C:\ProgramData\Anaconda3\envs\bank\lib\site-packages\sqlalchemy\orm\session.py", line 829, in commit
    self._prepare_impl()
  File "C:\ProgramData\Anaconda3\envs\bank\lib\site-packages\sqlalchemy\orm\session.py", line 808, in _prepare_impl
    self.session.flush()
  File "C:\ProgramData\Anaconda3\envs\bank\lib\site-packages\sqlalchemy\orm\session.py", line 3345, in flush
    self._flush(objects)
  File "C:\ProgramData\Anaconda3\envs\bank\lib\site-packages\sqlalchemy\orm\session.py", line 3485, in _flush
    transaction.rollback(_capture_exception=True)
  File "C:\ProgramData\Anaconda3\envs\bank\lib\site-packages\sqlalchemy\util\langhelpers.py", line 70, in __exit__
    compat.raise_(
  File "C:\ProgramData\Anaconda3\envs\bank\lib\site-packages\sqlalchemy\util\compat.py", line 207, in raise_
    raise exception
  File "C:\ProgramData\Anaconda3\envs\bank\lib\site-packages\sqlalchemy\orm\session.py", line 3445, in _flush
    flush_context.execute()
  File "C:\ProgramData\Anaconda3\envs\bank\lib\site-packages\sqlalchemy\orm\unitofwork.py", line 456, in execute
    rec.execute(self)
  File "C:\ProgramData\Anaconda3\envs\bank\lib\site-packages\sqlalchemy\orm\unitofwork.py", line 630, in execute
    util.preloaded.orm_persistence.save_obj(
  File "C:\ProgramData\Anaconda3\envs\bank\lib\site-packages\sqlalchemy\orm\persistence.py", line 244, in save_obj
    _emit_insert_statements(
  File "C:\ProgramData\Anaconda3\envs\bank\lib\site-packages\sqlalchemy\orm\persistence.py", line 1096, in _emit_insert_statements
    c = connection._execute_20(
  File "C:\ProgramData\Anaconda3\envs\bank\lib\site-packages\sqlalchemy\engine\base.py", line 1614, in _execute_20
    return meth(self, args_10style, kwargs_10style, execution_options)
  File "C:\ProgramData\Anaconda3\envs\bank\lib\site-packages\sqlalchemy\sql\elements.py", line 325, in _execute_on_connection
    return connection._execute_clauseelement(
  File "C:\ProgramData\Anaconda3\envs\bank\lib\site-packages\sqlalchemy\engine\base.py", line 1481, in _execute_clauseelement
    ret = self._execute_context(
  File "C:\ProgramData\Anaconda3\envs\bank\lib\site-packages\sqlalchemy\engine\base.py", line 1845, in _execute_context
    self._handle_dbapi_exception(
  File "C:\ProgramData\Anaconda3\envs\bank\lib\site-packages\sqlalchemy\engine\base.py", line 2026, in _handle_dbapi_exception
    util.raise_(
  File "C:\ProgramData\Anaconda3\envs\bank\lib\site-packages\sqlalchemy\util\compat.py", line 207, in raise_
    raise exception
  File "C:\ProgramData\Anaconda3\envs\bank\lib\site-packages\sqlalchemy\engine\base.py", line 1802, in _execute_context
    self.dialect.do_execute(
  File "C:\ProgramData\Anaconda3\envs\bank\lib\site-packages\sqlalchemy\engine\default.py", line 719, in do_execute
    cursor.execute(statement, parameters)
  File "C:\ProgramData\Anaconda3\envs\bank\lib\site-packages\pymysql\cursors.py", line 148, in execute
    result = self._query(query)
  File "C:\ProgramData\Anaconda3\envs\bank\lib\site-packages\pymysql\cursors.py", line 310, in _query
    conn.query(q)
  File "C:\ProgramData\Anaconda3\envs\bank\lib\site-packages\pymysql\connections.py", line 548, in query
    self._affected_rows = self._read_query_result(unbuffered=unbuffered)
  File "C:\ProgramData\Anaconda3\envs\bank\lib\site-packages\pymysql\connections.py", line 775, in _read_query_result
    result.read()
  File "C:\ProgramData\Anaconda3\envs\bank\lib\site-packages\pymysql\connections.py", line 1156, in read
    first_packet = self.connection._read_packet()
  File "C:\ProgramData\Anaconda3\envs\bank\lib\site-packages\pymysql\connections.py", line 725, in _read_packet
    packet.raise_for_error()
  File "C:\ProgramData\Anaconda3\envs\bank\lib\site-packages\pymysql\protocol.py", line 221, in raise_for_error
    err.raise_mysql_exception(self._data)
  File "C:\ProgramData\Anaconda3\envs\bank\lib\site-packages\pymysql\err.py", line 143, in raise_mysql_exception
    raise errorclass(errno, errval)
sqlalchemy.exc.IntegrityError: (pymysql.err.IntegrityError) (1062, "Duplicate entry '1' for key 'sequence.PRIMARY'")
[SQL: INSERT INTO sequence (id) VALUES (%(id)s)]
[parameters: {'id': 1}]
(Background on this error at: https://sqlalche.me/e/14/gkpj)
2022-02-02 06:55:39,656:utility.py:logger_expt:ERROR:(pymysql.err.IntegrityError) (1062, "Duplicate entry '1' for key 'sequence.PRIMARY'")
[SQL: INSERT INTO sequence (id) VALUES (%(id)s)]
[parameters: {'id': 1}]
(Background on this error at: https://sqlalche.me/e/14/gkpj)
Traceback (most recent call last):
  File "C:\ProgramData\Anaconda3\envs\bank\lib\site-packages\sqlalchemy\engine\base.py", line 1802, in _execute_context
    self.dialect.do_execute(
  File "C:\ProgramData\Anaconda3\envs\bank\lib\site-packages\sqlalchemy\engine\default.py", line 719, in do_execute
    cursor.execute(statement, parameters)
  File "C:\ProgramData\Anaconda3\envs\bank\lib\site-packages\pymysql\cursors.py", line 148, in execute
    result = self._query(query)
  File "C:\ProgramData\Anaconda3\envs\bank\lib\site-packages\pymysql\cursors.py", line 310, in _query
    conn.query(q)
  File "C:\ProgramData\Anaconda3\envs\bank\lib\site-packages\pymysql\connections.py", line 548, in query
    self._affected_rows = self._read_query_result(unbuffered=unbuffered)
  File "C:\ProgramData\Anaconda3\envs\bank\lib\site-packages\pymysql\connections.py", line 775, in _read_query_result
    result.read()
  File "C:\ProgramData\Anaconda3\envs\bank\lib\site-packages\pymysql\connections.py", line 1156, in read
    first_packet = self.connection._read_packet()
  File "C:\ProgramData\Anaconda3\envs\bank\lib\site-packages\pymysql\connections.py", line 725, in _read_packet
    packet.raise_for_error()
  File "C:\ProgramData\Anaconda3\envs\bank\lib\site-packages\pymysql\protocol.py", line 221, in raise_for_error
    err.raise_mysql_exception(self._data)
  File "C:\ProgramData\Anaconda3\envs\bank\lib\site-packages\pymysql\err.py", line 143, in raise_mysql_exception
    raise errorclass(errno, errval)
pymysql.err.IntegrityError: (1062, "Duplicate entry '1' for key 'sequence.PRIMARY'")

The above exception was the direct cause of the following exception:

Traceback (most recent call last):
  File "C:\Users\huang\OneDrive\14-code\bank\database.py", line 90, in new_rec_in_db
    session.commit()
  File "C:\ProgramData\Anaconda3\envs\bank\lib\site-packages\sqlalchemy\orm\session.py", line 1428, in commit
    self._transaction.commit(_to_root=self.future)
  File "C:\ProgramData\Anaconda3\envs\bank\lib\site-packages\sqlalchemy\orm\session.py", line 829, in commit
    self._prepare_impl()
  File "C:\ProgramData\Anaconda3\envs\bank\lib\site-packages\sqlalchemy\orm\session.py", line 808, in _prepare_impl
    self.session.flush()
  File "C:\ProgramData\Anaconda3\envs\bank\lib\site-packages\sqlalchemy\orm\session.py", line 3345, in flush
    self._flush(objects)
  File "C:\ProgramData\Anaconda3\envs\bank\lib\site-packages\sqlalchemy\orm\session.py", line 3485, in _flush
    transaction.rollback(_capture_exception=True)
  File "C:\ProgramData\Anaconda3\envs\bank\lib\site-packages\sqlalchemy\util\langhelpers.py", line 70, in __exit__
    compat.raise_(
  File "C:\ProgramData\Anaconda3\envs\bank\lib\site-packages\sqlalchemy\util\compat.py", line 207, in raise_
    raise exception
  File "C:\ProgramData\Anaconda3\envs\bank\lib\site-packages\sqlalchemy\orm\session.py", line 3445, in _flush
    flush_context.execute()
  File "C:\ProgramData\Anaconda3\envs\bank\lib\site-packages\sqlalchemy\orm\unitofwork.py", line 456, in execute
    rec.execute(self)
  File "C:\ProgramData\Anaconda3\envs\bank\lib\site-packages\sqlalchemy\orm\unitofwork.py", line 630, in execute
    util.preloaded.orm_persistence.save_obj(
  File "C:\ProgramData\Anaconda3\envs\bank\lib\site-packages\sqlalchemy\orm\persistence.py", line 244, in save_obj
    _emit_insert_statements(
  File "C:\ProgramData\Anaconda3\envs\bank\lib\site-packages\sqlalchemy\orm\persistence.py", line 1096, in _emit_insert_statements
    c = connection._execute_20(
  File "C:\ProgramData\Anaconda3\envs\bank\lib\site-packages\sqlalchemy\engine\base.py", line 1614, in _execute_20
    return meth(self, args_10style, kwargs_10style, execution_options)
  File "C:\ProgramData\Anaconda3\envs\bank\lib\site-packages\sqlalchemy\sql\elements.py", line 325, in _execute_on_connection
    return connection._execute_clauseelement(
  File "C:\ProgramData\Anaconda3\envs\bank\lib\site-packages\sqlalchemy\engine\base.py", line 1481, in _execute_clauseelement
    ret = self._execute_context(
  File "C:\ProgramData\Anaconda3\envs\bank\lib\site-packages\sqlalchemy\engine\base.py", line 1845, in _execute_context
    self._handle_dbapi_exception(
  File "C:\ProgramData\Anaconda3\envs\bank\lib\site-packages\sqlalchemy\engine\base.py", line 2026, in _handle_dbapi_exception
    util.raise_(
  File "C:\ProgramData\Anaconda3\envs\bank\lib\site-packages\sqlalchemy\util\compat.py", line 207, in raise_
    raise exception
  File "C:\ProgramData\Anaconda3\envs\bank\lib\site-packages\sqlalchemy\engine\base.py", line 1802, in _execute_context
    self.dialect.do_execute(
  File "C:\ProgramData\Anaconda3\envs\bank\lib\site-packages\sqlalchemy\engine\default.py", line 719, in do_execute
    cursor.execute(statement, parameters)
  File "C:\ProgramData\Anaconda3\envs\bank\lib\site-packages\pymysql\cursors.py", line 148, in execute
    result = self._query(query)
  File "C:\ProgramData\Anaconda3\envs\bank\lib\site-packages\pymysql\cursors.py", line 310, in _query
    conn.query(q)
  File "C:\ProgramData\Anaconda3\envs\bank\lib\site-packages\pymysql\connections.py", line 548, in query
    self._affected_rows = self._read_query_result(unbuffered=unbuffered)
  File "C:\ProgramData\Anaconda3\envs\bank\lib\site-packages\pymysql\connections.py", line 775, in _read_query_result
    result.read()
  File "C:\ProgramData\Anaconda3\envs\bank\lib\site-packages\pymysql\connections.py", line 1156, in read
    first_packet = self.connection._read_packet()
  File "C:\ProgramData\Anaconda3\envs\bank\lib\site-packages\pymysql\connections.py", line 725, in _read_packet
    packet.raise_for_error()
  File "C:\ProgramData\Anaconda3\envs\bank\lib\site-packages\pymysql\protocol.py", line 221, in raise_for_error
    err.raise_mysql_exception(self._data)
  File "C:\ProgramData\Anaconda3\envs\bank\lib\site-packages\pymysql\err.py", line 143, in raise_mysql_exception
    raise errorclass(errno, errval)
sqlalchemy.exc.IntegrityError: (pymysql.err.IntegrityError) (1062, "Duplicate entry '1' for key 'sequence.PRIMARY'")
[SQL: INSERT INTO sequence (id) VALUES (%(id)s)]
[parameters: {'id': 1}]
(Background on this error at: https://sqlalche.me/e/14/gkpj)
2022-02-02 06:57:53,579:utility.py:logger_expt:ERROR:(pymysql.err.IntegrityError) (1062, "Duplicate entry '1' for key 'sequence.PRIMARY'")
[SQL: INSERT INTO sequence (id) VALUES (%(id)s)]
[parameters: {'id': 1}]
(Background on this error at: https://sqlalche.me/e/14/gkpj)
Traceback (most recent call last):
  File "C:\ProgramData\Anaconda3\envs\bank\lib\site-packages\sqlalchemy\engine\base.py", line 1802, in _execute_context
    self.dialect.do_execute(
  File "C:\ProgramData\Anaconda3\envs\bank\lib\site-packages\sqlalchemy\engine\default.py", line 719, in do_execute
    cursor.execute(statement, parameters)
  File "C:\ProgramData\Anaconda3\envs\bank\lib\site-packages\pymysql\cursors.py", line 148, in execute
    result = self._query(query)
  File "C:\ProgramData\Anaconda3\envs\bank\lib\site-packages\pymysql\cursors.py", line 310, in _query
    conn.query(q)
  File "C:\ProgramData\Anaconda3\envs\bank\lib\site-packages\pymysql\connections.py", line 548, in query
    self._affected_rows = self._read_query_result(unbuffered=unbuffered)
  File "C:\ProgramData\Anaconda3\envs\bank\lib\site-packages\pymysql\connections.py", line 775, in _read_query_result
    result.read()
  File "C:\ProgramData\Anaconda3\envs\bank\lib\site-packages\pymysql\connections.py", line 1156, in read
    first_packet = self.connection._read_packet()
  File "C:\ProgramData\Anaconda3\envs\bank\lib\site-packages\pymysql\connections.py", line 725, in _read_packet
    packet.raise_for_error()
  File "C:\ProgramData\Anaconda3\envs\bank\lib\site-packages\pymysql\protocol.py", line 221, in raise_for_error
    err.raise_mysql_exception(self._data)
  File "C:\ProgramData\Anaconda3\envs\bank\lib\site-packages\pymysql\err.py", line 143, in raise_mysql_exception
    raise errorclass(errno, errval)
pymysql.err.IntegrityError: (1062, "Duplicate entry '1' for key 'sequence.PRIMARY'")

The above exception was the direct cause of the following exception:

Traceback (most recent call last):
  File "C:\Users\huang\OneDrive\14-code\bank\database.py", line 90, in new_rec_in_db
    session.commit()
  File "C:\ProgramData\Anaconda3\envs\bank\lib\site-packages\sqlalchemy\orm\session.py", line 1428, in commit
    self._transaction.commit(_to_root=self.future)
  File "C:\ProgramData\Anaconda3\envs\bank\lib\site-packages\sqlalchemy\orm\session.py", line 829, in commit
    self._prepare_impl()
  File "C:\ProgramData\Anaconda3\envs\bank\lib\site-packages\sqlalchemy\orm\session.py", line 808, in _prepare_impl
    self.session.flush()
  File "C:\ProgramData\Anaconda3\envs\bank\lib\site-packages\sqlalchemy\orm\session.py", line 3345, in flush
    self._flush(objects)
  File "C:\ProgramData\Anaconda3\envs\bank\lib\site-packages\sqlalchemy\orm\session.py", line 3485, in _flush
    transaction.rollback(_capture_exception=True)
  File "C:\ProgramData\Anaconda3\envs\bank\lib\site-packages\sqlalchemy\util\langhelpers.py", line 70, in __exit__
    compat.raise_(
  File "C:\ProgramData\Anaconda3\envs\bank\lib\site-packages\sqlalchemy\util\compat.py", line 207, in raise_
    raise exception
  File "C:\ProgramData\Anaconda3\envs\bank\lib\site-packages\sqlalchemy\orm\session.py", line 3445, in _flush
    flush_context.execute()
  File "C:\ProgramData\Anaconda3\envs\bank\lib\site-packages\sqlalchemy\orm\unitofwork.py", line 456, in execute
    rec.execute(self)
  File "C:\ProgramData\Anaconda3\envs\bank\lib\site-packages\sqlalchemy\orm\unitofwork.py", line 630, in execute
    util.preloaded.orm_persistence.save_obj(
  File "C:\ProgramData\Anaconda3\envs\bank\lib\site-packages\sqlalchemy\orm\persistence.py", line 244, in save_obj
    _emit_insert_statements(
  File "C:\ProgramData\Anaconda3\envs\bank\lib\site-packages\sqlalchemy\orm\persistence.py", line 1096, in _emit_insert_statements
    c = connection._execute_20(
  File "C:\ProgramData\Anaconda3\envs\bank\lib\site-packages\sqlalchemy\engine\base.py", line 1614, in _execute_20
    return meth(self, args_10style, kwargs_10style, execution_options)
  File "C:\ProgramData\Anaconda3\envs\bank\lib\site-packages\sqlalchemy\sql\elements.py", line 325, in _execute_on_connection
    return connection._execute_clauseelement(
  File "C:\ProgramData\Anaconda3\envs\bank\lib\site-packages\sqlalchemy\engine\base.py", line 1481, in _execute_clauseelement
    ret = self._execute_context(
  File "C:\ProgramData\Anaconda3\envs\bank\lib\site-packages\sqlalchemy\engine\base.py", line 1845, in _execute_context
    self._handle_dbapi_exception(
  File "C:\ProgramData\Anaconda3\envs\bank\lib\site-packages\sqlalchemy\engine\base.py", line 2026, in _handle_dbapi_exception
    util.raise_(
  File "C:\ProgramData\Anaconda3\envs\bank\lib\site-packages\sqlalchemy\util\compat.py", line 207, in raise_
    raise exception
  File "C:\ProgramData\Anaconda3\envs\bank\lib\site-packages\sqlalchemy\engine\base.py", line 1802, in _execute_context
    self.dialect.do_execute(
  File "C:\ProgramData\Anaconda3\envs\bank\lib\site-packages\sqlalchemy\engine\default.py", line 719, in do_execute
    cursor.execute(statement, parameters)
  File "C:\ProgramData\Anaconda3\envs\bank\lib\site-packages\pymysql\cursors.py", line 148, in execute
    result = self._query(query)
  File "C:\ProgramData\Anaconda3\envs\bank\lib\site-packages\pymysql\cursors.py", line 310, in _query
    conn.query(q)
  File "C:\ProgramData\Anaconda3\envs\bank\lib\site-packages\pymysql\connections.py", line 548, in query
    self._affected_rows = self._read_query_result(unbuffered=unbuffered)
  File "C:\ProgramData\Anaconda3\envs\bank\lib\site-packages\pymysql\connections.py", line 775, in _read_query_result
    result.read()
  File "C:\ProgramData\Anaconda3\envs\bank\lib\site-packages\pymysql\connections.py", line 1156, in read
    first_packet = self.connection._read_packet()
  File "C:\ProgramData\Anaconda3\envs\bank\lib\site-packages\pymysql\connections.py", line 725, in _read_packet
    packet.raise_for_error()
  File "C:\ProgramData\Anaconda3\envs\bank\lib\site-packages\pymysql\protocol.py", line 221, in raise_for_error
    err.raise_mysql_exception(self._data)
  File "C:\ProgramData\Anaconda3\envs\bank\lib\site-packages\pymysql\err.py", line 143, in raise_mysql_exception
    raise errorclass(errno, errval)
sqlalchemy.exc.IntegrityError: (pymysql.err.IntegrityError) (1062, "Duplicate entry '1' for key 'sequence.PRIMARY'")
[SQL: INSERT INTO sequence (id) VALUES (%(id)s)]
[parameters: {'id': 1}]
(Background on this error at: https://sqlalche.me/e/14/gkpj)
2022-02-02 07:17:40,449:utility.py:logger_expt:ERROR:Multiple rows were found when exactly one was required
Traceback (most recent call last):
  File "C:\Users\huang\OneDrive\14-code\bank\customer.py", line 60, in f_customer_not_exist
    rec = session.query(Customer).filter(Customer.name == p_name).filter(or_(Customer.address == p_addr,
  File "C:\ProgramData\Anaconda3\lib\site-packages\sqlalchemy\orm\query.py", line 2782, in one
    return self._iter().one()
  File "C:\ProgramData\Anaconda3\lib\site-packages\sqlalchemy\engine\result.py", line 1380, in one
    return self._only_one_row(True, True, False)
  File "C:\ProgramData\Anaconda3\lib\site-packages\sqlalchemy\engine\result.py", line 620, in _only_one_row
    raise exc.MultipleResultsFound(
sqlalchemy.exc.MultipleResultsFound: Multiple rows were found when exactly one was required
2022-02-02 07:17:40,464:utility.py:logger_expt:ERROR:Multiple rows were found when exactly one was required
Traceback (most recent call last):
  File "C:\Users\huang\OneDrive\14-code\bank\customer.py", line 60, in f_customer_not_exist
    rec = session.query(Customer).filter(Customer.name == p_name).filter(or_(Customer.address == p_addr,
  File "C:\ProgramData\Anaconda3\lib\site-packages\sqlalchemy\orm\query.py", line 2782, in one
    return self._iter().one()
  File "C:\ProgramData\Anaconda3\lib\site-packages\sqlalchemy\engine\result.py", line 1380, in one
    return self._only_one_row(True, True, False)
  File "C:\ProgramData\Anaconda3\lib\site-packages\sqlalchemy\engine\result.py", line 620, in _only_one_row
    raise exc.MultipleResultsFound(
sqlalchemy.exc.MultipleResultsFound: Multiple rows were found when exactly one was required
2022-02-02 07:18:50,446:utility.py:logger_expt:ERROR:No row was found when one was required
Traceback (most recent call last):
  File "C:\Users\huang\OneDrive\14-code\bank\bankaccount.py", line 113, in get_by_account_no
    rec = session.query(BankAccount).\
  File "C:\ProgramData\Anaconda3\lib\site-packages\sqlalchemy\orm\query.py", line 2782, in one
    return self._iter().one()
  File "C:\ProgramData\Anaconda3\lib\site-packages\sqlalchemy\engine\result.py", line 1380, in one
    return self._only_one_row(True, True, False)
  File "C:\ProgramData\Anaconda3\lib\site-packages\sqlalchemy\engine\result.py", line 569, in _only_one_row
    raise exc.NoResultFound(
sqlalchemy.exc.NoResultFound: No row was found when one was required
2022-02-02 07:18:50,462:utility.py:logger_expt:ERROR:No row was found when one was required
Traceback (most recent call last):
  File "C:\Users\huang\OneDrive\14-code\bank\bankaccount.py", line 132, in get_by_account_id
    rec = session.query(BankAccount).\
  File "C:\ProgramData\Anaconda3\lib\site-packages\sqlalchemy\orm\query.py", line 2782, in one
    return self._iter().one()
  File "C:\ProgramData\Anaconda3\lib\site-packages\sqlalchemy\engine\result.py", line 1380, in one
    return self._only_one_row(True, True, False)
  File "C:\ProgramData\Anaconda3\lib\site-packages\sqlalchemy\engine\result.py", line 569, in _only_one_row
    raise exc.NoResultFound(
sqlalchemy.exc.NoResultFound: No row was found when one was required
2022-02-02 07:18:50,462:utility.py:logger_expt:ERROR:Multiple rows were found when exactly one was required
Traceback (most recent call last):
  File "C:\Users\huang\OneDrive\14-code\bank\customer.py", line 60, in f_customer_not_exist
    rec = session.query(Customer).filter(Customer.name == p_name).filter(or_(Customer.address == p_addr,
  File "C:\ProgramData\Anaconda3\lib\site-packages\sqlalchemy\orm\query.py", line 2782, in one
    return self._iter().one()
  File "C:\ProgramData\Anaconda3\lib\site-packages\sqlalchemy\engine\result.py", line 1380, in one
    return self._only_one_row(True, True, False)
  File "C:\ProgramData\Anaconda3\lib\site-packages\sqlalchemy\engine\result.py", line 620, in _only_one_row
    raise exc.MultipleResultsFound(
sqlalchemy.exc.MultipleResultsFound: Multiple rows were found when exactly one was required
2022-02-02 07:18:50,478:utility.py:logger_expt:ERROR:Multiple rows were found when exactly one was required
Traceback (most recent call last):
  File "C:\Users\huang\OneDrive\14-code\bank\customer.py", line 60, in f_customer_not_exist
    rec = session.query(Customer).filter(Customer.name == p_name).filter(or_(Customer.address == p_addr,
  File "C:\ProgramData\Anaconda3\lib\site-packages\sqlalchemy\orm\query.py", line 2782, in one
    return self._iter().one()
  File "C:\ProgramData\Anaconda3\lib\site-packages\sqlalchemy\engine\result.py", line 1380, in one
    return self._only_one_row(True, True, False)
  File "C:\ProgramData\Anaconda3\lib\site-packages\sqlalchemy\engine\result.py", line 620, in _only_one_row
    raise exc.MultipleResultsFound(
sqlalchemy.exc.MultipleResultsFound: Multiple rows were found when exactly one was required
2022-02-02 07:19:04,581:utility.py:logger_expt:ERROR:No row was found when one was required
Traceback (most recent call last):
  File "C:\Users\huang\OneDrive\14-code\bank\bankaccount.py", line 113, in get_by_account_no
    rec = session.query(BankAccount).\
  File "C:\ProgramData\Anaconda3\lib\site-packages\sqlalchemy\orm\query.py", line 2782, in one
    return self._iter().one()
  File "C:\ProgramData\Anaconda3\lib\site-packages\sqlalchemy\engine\result.py", line 1380, in one
    return self._only_one_row(True, True, False)
  File "C:\ProgramData\Anaconda3\lib\site-packages\sqlalchemy\engine\result.py", line 569, in _only_one_row
    raise exc.NoResultFound(
sqlalchemy.exc.NoResultFound: No row was found when one was required
2022-02-02 07:19:04,597:utility.py:logger_expt:ERROR:No row was found when one was required
Traceback (most recent call last):
  File "C:\Users\huang\OneDrive\14-code\bank\bankaccount.py", line 132, in get_by_account_id
    rec = session.query(BankAccount).\
  File "C:\ProgramData\Anaconda3\lib\site-packages\sqlalchemy\orm\query.py", line 2782, in one
    return self._iter().one()
  File "C:\ProgramData\Anaconda3\lib\site-packages\sqlalchemy\engine\result.py", line 1380, in one
    return self._only_one_row(True, True, False)
  File "C:\ProgramData\Anaconda3\lib\site-packages\sqlalchemy\engine\result.py", line 569, in _only_one_row
    raise exc.NoResultFound(
sqlalchemy.exc.NoResultFound: No row was found when one was required
2022-02-02 07:19:04,613:utility.py:logger_expt:ERROR:Multiple rows were found when exactly one was required
Traceback (most recent call last):
  File "C:\Users\huang\OneDrive\14-code\bank\customer.py", line 60, in f_customer_not_exist
    rec = session.query(Customer).filter(Customer.name == p_name).filter(or_(Customer.address == p_addr,
  File "C:\ProgramData\Anaconda3\lib\site-packages\sqlalchemy\orm\query.py", line 2782, in one
    return self._iter().one()
  File "C:\ProgramData\Anaconda3\lib\site-packages\sqlalchemy\engine\result.py", line 1380, in one
    return self._only_one_row(True, True, False)
  File "C:\ProgramData\Anaconda3\lib\site-packages\sqlalchemy\engine\result.py", line 620, in _only_one_row
    raise exc.MultipleResultsFound(
sqlalchemy.exc.MultipleResultsFound: Multiple rows were found when exactly one was required
2022-02-02 07:19:04,613:utility.py:logger_expt:ERROR:Multiple rows were found when exactly one was required
Traceback (most recent call last):
  File "C:\Users\huang\OneDrive\14-code\bank\customer.py", line 60, in f_customer_not_exist
    rec = session.query(Customer).filter(Customer.name == p_name).filter(or_(Customer.address == p_addr,
  File "C:\ProgramData\Anaconda3\lib\site-packages\sqlalchemy\orm\query.py", line 2782, in one
    return self._iter().one()
  File "C:\ProgramData\Anaconda3\lib\site-packages\sqlalchemy\engine\result.py", line 1380, in one
    return self._only_one_row(True, True, False)
  File "C:\ProgramData\Anaconda3\lib\site-packages\sqlalchemy\engine\result.py", line 620, in _only_one_row
    raise exc.MultipleResultsFound(
sqlalchemy.exc.MultipleResultsFound: Multiple rows were found when exactly one was required
2022-02-02 07:20:44,937:utility.py:logger_expt:ERROR:No row was found when one was required
Traceback (most recent call last):
  File "C:\Users\huang\OneDrive\14-code\bank\bankaccount.py", line 113, in get_by_account_no
    rec = session.query(BankAccount).\
  File "C:\ProgramData\Anaconda3\lib\site-packages\sqlalchemy\orm\query.py", line 2782, in one
    return self._iter().one()
  File "C:\ProgramData\Anaconda3\lib\site-packages\sqlalchemy\engine\result.py", line 1380, in one
    return self._only_one_row(True, True, False)
  File "C:\ProgramData\Anaconda3\lib\site-packages\sqlalchemy\engine\result.py", line 569, in _only_one_row
    raise exc.NoResultFound(
sqlalchemy.exc.NoResultFound: No row was found when one was required
2022-02-02 07:20:44,953:utility.py:logger_expt:ERROR:No row was found when one was required
Traceback (most recent call last):
  File "C:\Users\huang\OneDrive\14-code\bank\bankaccount.py", line 132, in get_by_account_id
    rec = session.query(BankAccount).\
  File "C:\ProgramData\Anaconda3\lib\site-packages\sqlalchemy\orm\query.py", line 2782, in one
    return self._iter().one()
  File "C:\ProgramData\Anaconda3\lib\site-packages\sqlalchemy\engine\result.py", line 1380, in one
    return self._only_one_row(True, True, False)
  File "C:\ProgramData\Anaconda3\lib\site-packages\sqlalchemy\engine\result.py", line 569, in _only_one_row
    raise exc.NoResultFound(
sqlalchemy.exc.NoResultFound: No row was found when one was required
2022-02-02 07:20:44,968:utility.py:logger_expt:ERROR:Multiple rows were found when exactly one was required
Traceback (most recent call last):
  File "C:\Users\huang\OneDrive\14-code\bank\customer.py", line 60, in f_customer_not_exist
    rec = session.query(Customer).filter(Customer.name == p_name).filter(or_(Customer.address == p_addr,
  File "C:\ProgramData\Anaconda3\lib\site-packages\sqlalchemy\orm\query.py", line 2782, in one
    return self._iter().one()
  File "C:\ProgramData\Anaconda3\lib\site-packages\sqlalchemy\engine\result.py", line 1380, in one
    return self._only_one_row(True, True, False)
  File "C:\ProgramData\Anaconda3\lib\site-packages\sqlalchemy\engine\result.py", line 620, in _only_one_row
    raise exc.MultipleResultsFound(
sqlalchemy.exc.MultipleResultsFound: Multiple rows were found when exactly one was required
2022-02-02 07:20:44,984:utility.py:logger_expt:ERROR:Multiple rows were found when exactly one was required
Traceback (most recent call last):
  File "C:\Users\huang\OneDrive\14-code\bank\customer.py", line 60, in f_customer_not_exist
    rec = session.query(Customer).filter(Customer.name == p_name).filter(or_(Customer.address == p_addr,
  File "C:\ProgramData\Anaconda3\lib\site-packages\sqlalchemy\orm\query.py", line 2782, in one
    return self._iter().one()
  File "C:\ProgramData\Anaconda3\lib\site-packages\sqlalchemy\engine\result.py", line 1380, in one
    return self._only_one_row(True, True, False)
  File "C:\ProgramData\Anaconda3\lib\site-packages\sqlalchemy\engine\result.py", line 620, in _only_one_row
    raise exc.MultipleResultsFound(
sqlalchemy.exc.MultipleResultsFound: Multiple rows were found when exactly one was required
2022-02-02 07:32:18,955:utility.py:logger_expt:ERROR:No row was found when one was required
Traceback (most recent call last):
  File "C:\Users\huang\OneDrive\14-code\bank\bankaccount.py", line 113, in get_by_account_no
    rec = session.query(BankAccount).\
  File "C:\ProgramData\Anaconda3\lib\site-packages\sqlalchemy\orm\query.py", line 2782, in one
    return self._iter().one()
  File "C:\ProgramData\Anaconda3\lib\site-packages\sqlalchemy\engine\result.py", line 1380, in one
    return self._only_one_row(True, True, False)
  File "C:\ProgramData\Anaconda3\lib\site-packages\sqlalchemy\engine\result.py", line 569, in _only_one_row
    raise exc.NoResultFound(
sqlalchemy.exc.NoResultFound: No row was found when one was required
2022-02-02 07:32:18,955:utility.py:logger_expt:ERROR:No row was found when one was required
Traceback (most recent call last):
  File "C:\Users\huang\OneDrive\14-code\bank\bankaccount.py", line 132, in get_by_account_id
    rec = session.query(BankAccount).\
  File "C:\ProgramData\Anaconda3\lib\site-packages\sqlalchemy\orm\query.py", line 2782, in one
    return self._iter().one()
  File "C:\ProgramData\Anaconda3\lib\site-packages\sqlalchemy\engine\result.py", line 1380, in one
    return self._only_one_row(True, True, False)
  File "C:\ProgramData\Anaconda3\lib\site-packages\sqlalchemy\engine\result.py", line 569, in _only_one_row
    raise exc.NoResultFound(
sqlalchemy.exc.NoResultFound: No row was found when one was required
2022-02-02 07:32:18,970:utility.py:logger_expt:ERROR:Multiple rows were found when exactly one was required
Traceback (most recent call last):
  File "C:\Users\huang\OneDrive\14-code\bank\customer.py", line 60, in f_customer_not_exist
    rec = session.query(Customer).filter(Customer.name == p_name).filter(or_(Customer.address == p_addr,
  File "C:\ProgramData\Anaconda3\lib\site-packages\sqlalchemy\orm\query.py", line 2782, in one
    return self._iter().one()
  File "C:\ProgramData\Anaconda3\lib\site-packages\sqlalchemy\engine\result.py", line 1380, in one
    return self._only_one_row(True, True, False)
  File "C:\ProgramData\Anaconda3\lib\site-packages\sqlalchemy\engine\result.py", line 620, in _only_one_row
    raise exc.MultipleResultsFound(
sqlalchemy.exc.MultipleResultsFound: Multiple rows were found when exactly one was required
2022-02-02 07:32:18,970:utility.py:logger_expt:ERROR:Multiple rows were found when exactly one was required
Traceback (most recent call last):
  File "C:\Users\huang\OneDrive\14-code\bank\customer.py", line 60, in f_customer_not_exist
    rec = session.query(Customer).filter(Customer.name == p_name).filter(or_(Customer.address == p_addr,
  File "C:\ProgramData\Anaconda3\lib\site-packages\sqlalchemy\orm\query.py", line 2782, in one
    return self._iter().one()
  File "C:\ProgramData\Anaconda3\lib\site-packages\sqlalchemy\engine\result.py", line 1380, in one
    return self._only_one_row(True, True, False)
  File "C:\ProgramData\Anaconda3\lib\site-packages\sqlalchemy\engine\result.py", line 620, in _only_one_row
    raise exc.MultipleResultsFound(
sqlalchemy.exc.MultipleResultsFound: Multiple rows were found when exactly one was required
2022-02-02 07:33:07,771:utility.py:logger_expt:ERROR:No row was found when one was required
Traceback (most recent call last):
  File "C:\Users\huang\OneDrive\14-code\bank\bankaccount.py", line 113, in get_by_account_no
    rec = session.query(BankAccount).\
  File "C:\ProgramData\Anaconda3\lib\site-packages\sqlalchemy\orm\query.py", line 2782, in one
    return self._iter().one()
  File "C:\ProgramData\Anaconda3\lib\site-packages\sqlalchemy\engine\result.py", line 1380, in one
    return self._only_one_row(True, True, False)
  File "C:\ProgramData\Anaconda3\lib\site-packages\sqlalchemy\engine\result.py", line 569, in _only_one_row
    raise exc.NoResultFound(
sqlalchemy.exc.NoResultFound: No row was found when one was required
2022-02-02 07:33:07,787:utility.py:logger_expt:ERROR:No row was found when one was required
Traceback (most recent call last):
  File "C:\Users\huang\OneDrive\14-code\bank\bankaccount.py", line 132, in get_by_account_id
    rec = session.query(BankAccount).\
  File "C:\ProgramData\Anaconda3\lib\site-packages\sqlalchemy\orm\query.py", line 2782, in one
    return self._iter().one()
  File "C:\ProgramData\Anaconda3\lib\site-packages\sqlalchemy\engine\result.py", line 1380, in one
    return self._only_one_row(True, True, False)
  File "C:\ProgramData\Anaconda3\lib\site-packages\sqlalchemy\engine\result.py", line 569, in _only_one_row
    raise exc.NoResultFound(
sqlalchemy.exc.NoResultFound: No row was found when one was required
2022-02-02 07:33:07,803:utility.py:logger_expt:ERROR:Multiple rows were found when exactly one was required
Traceback (most recent call last):
  File "C:\Users\huang\OneDrive\14-code\bank\customer.py", line 60, in f_customer_not_exist
    rec = session.query(Customer).filter(Customer.name == p_name).filter(or_(Customer.address == p_addr,
  File "C:\ProgramData\Anaconda3\lib\site-packages\sqlalchemy\orm\query.py", line 2782, in one
    return self._iter().one()
  File "C:\ProgramData\Anaconda3\lib\site-packages\sqlalchemy\engine\result.py", line 1380, in one
    return self._only_one_row(True, True, False)
  File "C:\ProgramData\Anaconda3\lib\site-packages\sqlalchemy\engine\result.py", line 620, in _only_one_row
    raise exc.MultipleResultsFound(
sqlalchemy.exc.MultipleResultsFound: Multiple rows were found when exactly one was required
2022-02-02 07:33:07,803:utility.py:logger_expt:ERROR:Multiple rows were found when exactly one was required
Traceback (most recent call last):
  File "C:\Users\huang\OneDrive\14-code\bank\customer.py", line 60, in f_customer_not_exist
    rec = session.query(Customer).filter(Customer.name == p_name).filter(or_(Customer.address == p_addr,
  File "C:\ProgramData\Anaconda3\lib\site-packages\sqlalchemy\orm\query.py", line 2782, in one
    return self._iter().one()
  File "C:\ProgramData\Anaconda3\lib\site-packages\sqlalchemy\engine\result.py", line 1380, in one
    return self._only_one_row(True, True, False)
  File "C:\ProgramData\Anaconda3\lib\site-packages\sqlalchemy\engine\result.py", line 620, in _only_one_row
    raise exc.MultipleResultsFound(
sqlalchemy.exc.MultipleResultsFound: Multiple rows were found when exactly one was required
2022-02-02 07:34:03,533:utility.py:logger_expt:ERROR:No row was found when one was required
Traceback (most recent call last):
  File "C:\Users\huang\OneDrive\14-code\bank\bankaccount.py", line 113, in get_by_account_no
    rec = session.query(BankAccount).\
  File "C:\ProgramData\Anaconda3\lib\site-packages\sqlalchemy\orm\query.py", line 2782, in one
    return self._iter().one()
  File "C:\ProgramData\Anaconda3\lib\site-packages\sqlalchemy\engine\result.py", line 1380, in one
    return self._only_one_row(True, True, False)
  File "C:\ProgramData\Anaconda3\lib\site-packages\sqlalchemy\engine\result.py", line 569, in _only_one_row
    raise exc.NoResultFound(
sqlalchemy.exc.NoResultFound: No row was found when one was required
2022-02-02 07:34:03,549:utility.py:logger_expt:ERROR:No row was found when one was required
Traceback (most recent call last):
  File "C:\Users\huang\OneDrive\14-code\bank\bankaccount.py", line 132, in get_by_account_id
    rec = session.query(BankAccount).\
  File "C:\ProgramData\Anaconda3\lib\site-packages\sqlalchemy\orm\query.py", line 2782, in one
    return self._iter().one()
  File "C:\ProgramData\Anaconda3\lib\site-packages\sqlalchemy\engine\result.py", line 1380, in one
    return self._only_one_row(True, True, False)
  File "C:\ProgramData\Anaconda3\lib\site-packages\sqlalchemy\engine\result.py", line 569, in _only_one_row
    raise exc.NoResultFound(
sqlalchemy.exc.NoResultFound: No row was found when one was required
2022-02-02 07:34:03,549:utility.py:logger_expt:ERROR:Multiple rows were found when exactly one was required
Traceback (most recent call last):
  File "C:\Users\huang\OneDrive\14-code\bank\customer.py", line 60, in f_customer_not_exist
    rec = session.query(Customer).filter(Customer.name == p_name).filter(or_(Customer.address == p_addr,
  File "C:\ProgramData\Anaconda3\lib\site-packages\sqlalchemy\orm\query.py", line 2782, in one
    return self._iter().one()
  File "C:\ProgramData\Anaconda3\lib\site-packages\sqlalchemy\engine\result.py", line 1380, in one
    return self._only_one_row(True, True, False)
  File "C:\ProgramData\Anaconda3\lib\site-packages\sqlalchemy\engine\result.py", line 620, in _only_one_row
    raise exc.MultipleResultsFound(
sqlalchemy.exc.MultipleResultsFound: Multiple rows were found when exactly one was required
2022-02-02 07:34:03,564:utility.py:logger_expt:ERROR:Multiple rows were found when exactly one was required
Traceback (most recent call last):
  File "C:\Users\huang\OneDrive\14-code\bank\customer.py", line 60, in f_customer_not_exist
    rec = session.query(Customer).filter(Customer.name == p_name).filter(or_(Customer.address == p_addr,
  File "C:\ProgramData\Anaconda3\lib\site-packages\sqlalchemy\orm\query.py", line 2782, in one
    return self._iter().one()
  File "C:\ProgramData\Anaconda3\lib\site-packages\sqlalchemy\engine\result.py", line 1380, in one
    return self._only_one_row(True, True, False)
  File "C:\ProgramData\Anaconda3\lib\site-packages\sqlalchemy\engine\result.py", line 620, in _only_one_row
    raise exc.MultipleResultsFound(
sqlalchemy.exc.MultipleResultsFound: Multiple rows were found when exactly one was required
2022-02-02 07:35:48,687:utility.py:logger_expt:ERROR:No row was found when one was required
Traceback (most recent call last):
  File "C:\Users\huang\OneDrive\14-code\bank\bankaccount.py", line 113, in get_by_account_no
    rec = session.query(BankAccount).\
  File "C:\ProgramData\Anaconda3\lib\site-packages\sqlalchemy\orm\query.py", line 2782, in one
    return self._iter().one()
  File "C:\ProgramData\Anaconda3\lib\site-packages\sqlalchemy\engine\result.py", line 1380, in one
    return self._only_one_row(True, True, False)
  File "C:\ProgramData\Anaconda3\lib\site-packages\sqlalchemy\engine\result.py", line 569, in _only_one_row
    raise exc.NoResultFound(
sqlalchemy.exc.NoResultFound: No row was found when one was required
2022-02-02 07:35:48,687:utility.py:logger_expt:ERROR:No row was found when one was required
Traceback (most recent call last):
  File "C:\Users\huang\OneDrive\14-code\bank\bankaccount.py", line 132, in get_by_account_id
    rec = session.query(BankAccount).\
  File "C:\ProgramData\Anaconda3\lib\site-packages\sqlalchemy\orm\query.py", line 2782, in one
    return self._iter().one()
  File "C:\ProgramData\Anaconda3\lib\site-packages\sqlalchemy\engine\result.py", line 1380, in one
    return self._only_one_row(True, True, False)
  File "C:\ProgramData\Anaconda3\lib\site-packages\sqlalchemy\engine\result.py", line 569, in _only_one_row
    raise exc.NoResultFound(
sqlalchemy.exc.NoResultFound: No row was found when one was required
2022-02-02 07:35:48,703:utility.py:logger_expt:ERROR:Multiple rows were found when exactly one was required
Traceback (most recent call last):
  File "C:\Users\huang\OneDrive\14-code\bank\customer.py", line 60, in f_customer_not_exist
    rec = session.query(Customer).filter(Customer.name == p_name).filter(or_(Customer.address == p_addr,
  File "C:\ProgramData\Anaconda3\lib\site-packages\sqlalchemy\orm\query.py", line 2782, in one
    return self._iter().one()
  File "C:\ProgramData\Anaconda3\lib\site-packages\sqlalchemy\engine\result.py", line 1380, in one
    return self._only_one_row(True, True, False)
  File "C:\ProgramData\Anaconda3\lib\site-packages\sqlalchemy\engine\result.py", line 620, in _only_one_row
    raise exc.MultipleResultsFound(
sqlalchemy.exc.MultipleResultsFound: Multiple rows were found when exactly one was required
2022-02-02 07:35:48,703:utility.py:logger_expt:ERROR:Multiple rows were found when exactly one was required
Traceback (most recent call last):
  File "C:\Users\huang\OneDrive\14-code\bank\customer.py", line 60, in f_customer_not_exist
    rec = session.query(Customer).filter(Customer.name == p_name).filter(or_(Customer.address == p_addr,
  File "C:\ProgramData\Anaconda3\lib\site-packages\sqlalchemy\orm\query.py", line 2782, in one
    return self._iter().one()
  File "C:\ProgramData\Anaconda3\lib\site-packages\sqlalchemy\engine\result.py", line 1380, in one
    return self._only_one_row(True, True, False)
  File "C:\ProgramData\Anaconda3\lib\site-packages\sqlalchemy\engine\result.py", line 620, in _only_one_row
    raise exc.MultipleResultsFound(
sqlalchemy.exc.MultipleResultsFound: Multiple rows were found when exactly one was required
2022-02-02 10:01:12,626:utility.py:logger_expt:ERROR:No row was found when one was required
Traceback (most recent call last):
  File "C:\Users\huang\OneDrive\14-code\bank\bankaccount.py", line 128, in get_by_account_id
    rec = session.query(BankAccount).\
  File "C:\ProgramData\Anaconda3\lib\site-packages\sqlalchemy\orm\query.py", line 2782, in one
    return self._iter().one()
  File "C:\ProgramData\Anaconda3\lib\site-packages\sqlalchemy\engine\result.py", line 1380, in one
    return self._only_one_row(True, True, False)
  File "C:\ProgramData\Anaconda3\lib\site-packages\sqlalchemy\engine\result.py", line 569, in _only_one_row
    raise exc.NoResultFound(
sqlalchemy.exc.NoResultFound: No row was found when one was required
2022-02-02 10:02:17,966:utility.py:logger_expt:ERROR:No row was found when one was required
Traceback (most recent call last):
  File "C:\Users\huang\OneDrive\14-code\bank\bankaccount.py", line 128, in get_by_account_id
    rec = session.query(BankAccount).\
  File "C:\ProgramData\Anaconda3\lib\site-packages\sqlalchemy\orm\query.py", line 2782, in one
    return self._iter().one()
  File "C:\ProgramData\Anaconda3\lib\site-packages\sqlalchemy\engine\result.py", line 1380, in one
    return self._only_one_row(True, True, False)
  File "C:\ProgramData\Anaconda3\lib\site-packages\sqlalchemy\engine\result.py", line 569, in _only_one_row
    raise exc.NoResultFound(
sqlalchemy.exc.NoResultFound: No row was found when one was required
2022-02-02 14:39:20,027:utility.py:logger_expt:ERROR:(pymysql.err.OperationalError) (1054, "Unknown column 'level' in 'field list'")
[SQL: INSERT INTO employee (name, level, project) VALUES (%(name)s, %(level)s, %(project)s)]
[parameters: {'name': 'tom', 'level': None, 'project': None}]
(Background on this error at: https://sqlalche.me/e/14/e3q8)
Traceback (most recent call last):
  File "C:\ProgramData\Anaconda3\envs\bank\lib\site-packages\sqlalchemy\engine\base.py", line 1802, in _execute_context
    self.dialect.do_execute(
  File "C:\ProgramData\Anaconda3\envs\bank\lib\site-packages\sqlalchemy\engine\default.py", line 719, in do_execute
    cursor.execute(statement, parameters)
  File "C:\ProgramData\Anaconda3\envs\bank\lib\site-packages\pymysql\cursors.py", line 148, in execute
    result = self._query(query)
  File "C:\ProgramData\Anaconda3\envs\bank\lib\site-packages\pymysql\cursors.py", line 310, in _query
    conn.query(q)
  File "C:\ProgramData\Anaconda3\envs\bank\lib\site-packages\pymysql\connections.py", line 548, in query
    self._affected_rows = self._read_query_result(unbuffered=unbuffered)
  File "C:\ProgramData\Anaconda3\envs\bank\lib\site-packages\pymysql\connections.py", line 775, in _read_query_result
    result.read()
  File "C:\ProgramData\Anaconda3\envs\bank\lib\site-packages\pymysql\connections.py", line 1156, in read
    first_packet = self.connection._read_packet()
  File "C:\ProgramData\Anaconda3\envs\bank\lib\site-packages\pymysql\connections.py", line 725, in _read_packet
    packet.raise_for_error()
  File "C:\ProgramData\Anaconda3\envs\bank\lib\site-packages\pymysql\protocol.py", line 221, in raise_for_error
    err.raise_mysql_exception(self._data)
  File "C:\ProgramData\Anaconda3\envs\bank\lib\site-packages\pymysql\err.py", line 143, in raise_mysql_exception
    raise errorclass(errno, errval)
pymysql.err.OperationalError: (1054, "Unknown column 'level' in 'field list'")

The above exception was the direct cause of the following exception:

Traceback (most recent call last):
  File "C:\Users\huang\OneDrive\14-code\bank\database.py", line 89, in new_rec_in_db
    session.commit()
  File "C:\ProgramData\Anaconda3\envs\bank\lib\site-packages\sqlalchemy\orm\session.py", line 1428, in commit
    self._transaction.commit(_to_root=self.future)
  File "C:\ProgramData\Anaconda3\envs\bank\lib\site-packages\sqlalchemy\orm\session.py", line 829, in commit
    self._prepare_impl()
  File "C:\ProgramData\Anaconda3\envs\bank\lib\site-packages\sqlalchemy\orm\session.py", line 808, in _prepare_impl
    self.session.flush()
  File "C:\ProgramData\Anaconda3\envs\bank\lib\site-packages\sqlalchemy\orm\session.py", line 3345, in flush
    self._flush(objects)
  File "C:\ProgramData\Anaconda3\envs\bank\lib\site-packages\sqlalchemy\orm\session.py", line 3485, in _flush
    transaction.rollback(_capture_exception=True)
  File "C:\ProgramData\Anaconda3\envs\bank\lib\site-packages\sqlalchemy\util\langhelpers.py", line 70, in __exit__
    compat.raise_(
  File "C:\ProgramData\Anaconda3\envs\bank\lib\site-packages\sqlalchemy\util\compat.py", line 207, in raise_
    raise exception
  File "C:\ProgramData\Anaconda3\envs\bank\lib\site-packages\sqlalchemy\orm\session.py", line 3445, in _flush
    flush_context.execute()
  File "C:\ProgramData\Anaconda3\envs\bank\lib\site-packages\sqlalchemy\orm\unitofwork.py", line 456, in execute
    rec.execute(self)
  File "C:\ProgramData\Anaconda3\envs\bank\lib\site-packages\sqlalchemy\orm\unitofwork.py", line 630, in execute
    util.preloaded.orm_persistence.save_obj(
  File "C:\ProgramData\Anaconda3\envs\bank\lib\site-packages\sqlalchemy\orm\persistence.py", line 244, in save_obj
    _emit_insert_statements(
  File "C:\ProgramData\Anaconda3\envs\bank\lib\site-packages\sqlalchemy\orm\persistence.py", line 1221, in _emit_insert_statements
    result = connection._execute_20(
  File "C:\ProgramData\Anaconda3\envs\bank\lib\site-packages\sqlalchemy\engine\base.py", line 1614, in _execute_20
    return meth(self, args_10style, kwargs_10style, execution_options)
  File "C:\ProgramData\Anaconda3\envs\bank\lib\site-packages\sqlalchemy\sql\elements.py", line 325, in _execute_on_connection
    return connection._execute_clauseelement(
  File "C:\ProgramData\Anaconda3\envs\bank\lib\site-packages\sqlalchemy\engine\base.py", line 1481, in _execute_clauseelement
    ret = self._execute_context(
  File "C:\ProgramData\Anaconda3\envs\bank\lib\site-packages\sqlalchemy\engine\base.py", line 1845, in _execute_context
    self._handle_dbapi_exception(
  File "C:\ProgramData\Anaconda3\envs\bank\lib\site-packages\sqlalchemy\engine\base.py", line 2026, in _handle_dbapi_exception
    util.raise_(
  File "C:\ProgramData\Anaconda3\envs\bank\lib\site-packages\sqlalchemy\util\compat.py", line 207, in raise_
    raise exception
  File "C:\ProgramData\Anaconda3\envs\bank\lib\site-packages\sqlalchemy\engine\base.py", line 1802, in _execute_context
    self.dialect.do_execute(
  File "C:\ProgramData\Anaconda3\envs\bank\lib\site-packages\sqlalchemy\engine\default.py", line 719, in do_execute
    cursor.execute(statement, parameters)
  File "C:\ProgramData\Anaconda3\envs\bank\lib\site-packages\pymysql\cursors.py", line 148, in execute
    result = self._query(query)
  File "C:\ProgramData\Anaconda3\envs\bank\lib\site-packages\pymysql\cursors.py", line 310, in _query
    conn.query(q)
  File "C:\ProgramData\Anaconda3\envs\bank\lib\site-packages\pymysql\connections.py", line 548, in query
    self._affected_rows = self._read_query_result(unbuffered=unbuffered)
  File "C:\ProgramData\Anaconda3\envs\bank\lib\site-packages\pymysql\connections.py", line 775, in _read_query_result
    result.read()
  File "C:\ProgramData\Anaconda3\envs\bank\lib\site-packages\pymysql\connections.py", line 1156, in read
    first_packet = self.connection._read_packet()
  File "C:\ProgramData\Anaconda3\envs\bank\lib\site-packages\pymysql\connections.py", line 725, in _read_packet
    packet.raise_for_error()
  File "C:\ProgramData\Anaconda3\envs\bank\lib\site-packages\pymysql\protocol.py", line 221, in raise_for_error
    err.raise_mysql_exception(self._data)
  File "C:\ProgramData\Anaconda3\envs\bank\lib\site-packages\pymysql\err.py", line 143, in raise_mysql_exception
    raise errorclass(errno, errval)
sqlalchemy.exc.OperationalError: (pymysql.err.OperationalError) (1054, "Unknown column 'level' in 'field list'")
[SQL: INSERT INTO employee (name, level, project) VALUES (%(name)s, %(level)s, %(project)s)]
[parameters: {'name': 'tom', 'level': None, 'project': None}]
(Background on this error at: https://sqlalche.me/e/14/e3q8)
2022-02-02 14:39:40,962:utility.py:logger_expt:ERROR:(pymysql.err.OperationalError) (1054, "Unknown column 'level' in 'field list'")
[SQL: INSERT INTO employee (name, level, project) VALUES (%(name)s, %(level)s, %(project)s)]
[parameters: {'name': 'tom', 'level': None, 'project': None}]
(Background on this error at: https://sqlalche.me/e/14/e3q8)
Traceback (most recent call last):
  File "C:\ProgramData\Anaconda3\envs\bank\lib\site-packages\sqlalchemy\engine\base.py", line 1802, in _execute_context
    self.dialect.do_execute(
  File "C:\ProgramData\Anaconda3\envs\bank\lib\site-packages\sqlalchemy\engine\default.py", line 719, in do_execute
    cursor.execute(statement, parameters)
  File "C:\ProgramData\Anaconda3\envs\bank\lib\site-packages\pymysql\cursors.py", line 148, in execute
    result = self._query(query)
  File "C:\ProgramData\Anaconda3\envs\bank\lib\site-packages\pymysql\cursors.py", line 310, in _query
    conn.query(q)
  File "C:\ProgramData\Anaconda3\envs\bank\lib\site-packages\pymysql\connections.py", line 548, in query
    self._affected_rows = self._read_query_result(unbuffered=unbuffered)
  File "C:\ProgramData\Anaconda3\envs\bank\lib\site-packages\pymysql\connections.py", line 775, in _read_query_result
    result.read()
  File "C:\ProgramData\Anaconda3\envs\bank\lib\site-packages\pymysql\connections.py", line 1156, in read
    first_packet = self.connection._read_packet()
  File "C:\ProgramData\Anaconda3\envs\bank\lib\site-packages\pymysql\connections.py", line 725, in _read_packet
    packet.raise_for_error()
  File "C:\ProgramData\Anaconda3\envs\bank\lib\site-packages\pymysql\protocol.py", line 221, in raise_for_error
    err.raise_mysql_exception(self._data)
  File "C:\ProgramData\Anaconda3\envs\bank\lib\site-packages\pymysql\err.py", line 143, in raise_mysql_exception
    raise errorclass(errno, errval)
pymysql.err.OperationalError: (1054, "Unknown column 'level' in 'field list'")

The above exception was the direct cause of the following exception:

Traceback (most recent call last):
  File "C:\Users\huang\OneDrive\14-code\bank\database.py", line 89, in new_rec_in_db
    session.commit()
  File "C:\ProgramData\Anaconda3\envs\bank\lib\site-packages\sqlalchemy\orm\session.py", line 1428, in commit
    self._transaction.commit(_to_root=self.future)
  File "C:\ProgramData\Anaconda3\envs\bank\lib\site-packages\sqlalchemy\orm\session.py", line 829, in commit
    self._prepare_impl()
  File "C:\ProgramData\Anaconda3\envs\bank\lib\site-packages\sqlalchemy\orm\session.py", line 808, in _prepare_impl
    self.session.flush()
  File "C:\ProgramData\Anaconda3\envs\bank\lib\site-packages\sqlalchemy\orm\session.py", line 3345, in flush
    self._flush(objects)
  File "C:\ProgramData\Anaconda3\envs\bank\lib\site-packages\sqlalchemy\orm\session.py", line 3485, in _flush
    transaction.rollback(_capture_exception=True)
  File "C:\ProgramData\Anaconda3\envs\bank\lib\site-packages\sqlalchemy\util\langhelpers.py", line 70, in __exit__
    compat.raise_(
  File "C:\ProgramData\Anaconda3\envs\bank\lib\site-packages\sqlalchemy\util\compat.py", line 207, in raise_
    raise exception
  File "C:\ProgramData\Anaconda3\envs\bank\lib\site-packages\sqlalchemy\orm\session.py", line 3445, in _flush
    flush_context.execute()
  File "C:\ProgramData\Anaconda3\envs\bank\lib\site-packages\sqlalchemy\orm\unitofwork.py", line 456, in execute
    rec.execute(self)
  File "C:\ProgramData\Anaconda3\envs\bank\lib\site-packages\sqlalchemy\orm\unitofwork.py", line 630, in execute
    util.preloaded.orm_persistence.save_obj(
  File "C:\ProgramData\Anaconda3\envs\bank\lib\site-packages\sqlalchemy\orm\persistence.py", line 244, in save_obj
    _emit_insert_statements(
  File "C:\ProgramData\Anaconda3\envs\bank\lib\site-packages\sqlalchemy\orm\persistence.py", line 1221, in _emit_insert_statements
    result = connection._execute_20(
  File "C:\ProgramData\Anaconda3\envs\bank\lib\site-packages\sqlalchemy\engine\base.py", line 1614, in _execute_20
    return meth(self, args_10style, kwargs_10style, execution_options)
  File "C:\ProgramData\Anaconda3\envs\bank\lib\site-packages\sqlalchemy\sql\elements.py", line 325, in _execute_on_connection
    return connection._execute_clauseelement(
  File "C:\ProgramData\Anaconda3\envs\bank\lib\site-packages\sqlalchemy\engine\base.py", line 1481, in _execute_clauseelement
    ret = self._execute_context(
  File "C:\ProgramData\Anaconda3\envs\bank\lib\site-packages\sqlalchemy\engine\base.py", line 1845, in _execute_context
    self._handle_dbapi_exception(
  File "C:\ProgramData\Anaconda3\envs\bank\lib\site-packages\sqlalchemy\engine\base.py", line 2026, in _handle_dbapi_exception
    util.raise_(
  File "C:\ProgramData\Anaconda3\envs\bank\lib\site-packages\sqlalchemy\util\compat.py", line 207, in raise_
    raise exception
  File "C:\ProgramData\Anaconda3\envs\bank\lib\site-packages\sqlalchemy\engine\base.py", line 1802, in _execute_context
    self.dialect.do_execute(
  File "C:\ProgramData\Anaconda3\envs\bank\lib\site-packages\sqlalchemy\engine\default.py", line 719, in do_execute
    cursor.execute(statement, parameters)
  File "C:\ProgramData\Anaconda3\envs\bank\lib\site-packages\pymysql\cursors.py", line 148, in execute
    result = self._query(query)
  File "C:\ProgramData\Anaconda3\envs\bank\lib\site-packages\pymysql\cursors.py", line 310, in _query
    conn.query(q)
  File "C:\ProgramData\Anaconda3\envs\bank\lib\site-packages\pymysql\connections.py", line 548, in query
    self._affected_rows = self._read_query_result(unbuffered=unbuffered)
  File "C:\ProgramData\Anaconda3\envs\bank\lib\site-packages\pymysql\connections.py", line 775, in _read_query_result
    result.read()
  File "C:\ProgramData\Anaconda3\envs\bank\lib\site-packages\pymysql\connections.py", line 1156, in read
    first_packet = self.connection._read_packet()
  File "C:\ProgramData\Anaconda3\envs\bank\lib\site-packages\pymysql\connections.py", line 725, in _read_packet
    packet.raise_for_error()
  File "C:\ProgramData\Anaconda3\envs\bank\lib\site-packages\pymysql\protocol.py", line 221, in raise_for_error
    err.raise_mysql_exception(self._data)
  File "C:\ProgramData\Anaconda3\envs\bank\lib\site-packages\pymysql\err.py", line 143, in raise_mysql_exception
    raise errorclass(errno, errval)
sqlalchemy.exc.OperationalError: (pymysql.err.OperationalError) (1054, "Unknown column 'level' in 'field list'")
[SQL: INSERT INTO employee (name, level, project) VALUES (%(name)s, %(level)s, %(project)s)]
[parameters: {'name': 'tom', 'level': None, 'project': None}]
(Background on this error at: https://sqlalche.me/e/14/e3q8)
2022-02-02 14:55:43,341:utility.py:logger_expt:ERROR:Multiple rows were found when exactly one was required
Traceback (most recent call last):
  File "C:\Users\huang\OneDrive\14-code\bank\customer.py", line 50, in f_customer_not_exist
    rec = session.query(Customer).filter(Customer.name == p_name).filter(or_(Customer.address == p_addr,
  File "C:\ProgramData\Anaconda3\lib\site-packages\sqlalchemy\orm\query.py", line 2782, in one
    return self._iter().one()
  File "C:\ProgramData\Anaconda3\lib\site-packages\sqlalchemy\engine\result.py", line 1380, in one
    return self._only_one_row(True, True, False)
  File "C:\ProgramData\Anaconda3\lib\site-packages\sqlalchemy\engine\result.py", line 620, in _only_one_row
    raise exc.MultipleResultsFound(
sqlalchemy.exc.MultipleResultsFound: Multiple rows were found when exactly one was required
2022-02-02 14:55:43,357:utility.py:logger_expt:ERROR:Multiple rows were found when exactly one was required
Traceback (most recent call last):
  File "C:\Users\huang\OneDrive\14-code\bank\customer.py", line 50, in f_customer_not_exist
    rec = session.query(Customer).filter(Customer.name == p_name).filter(or_(Customer.address == p_addr,
  File "C:\ProgramData\Anaconda3\lib\site-packages\sqlalchemy\orm\query.py", line 2782, in one
    return self._iter().one()
  File "C:\ProgramData\Anaconda3\lib\site-packages\sqlalchemy\engine\result.py", line 1380, in one
    return self._only_one_row(True, True, False)
  File "C:\ProgramData\Anaconda3\lib\site-packages\sqlalchemy\engine\result.py", line 620, in _only_one_row
    raise exc.MultipleResultsFound(
sqlalchemy.exc.MultipleResultsFound: Multiple rows were found when exactly one was required
2022-02-02 18:24:08,628:utility.py:logger_expt:ERROR:(pymysql.err.OperationalError) (1364, "Field 'ticket_id' doesn't have a default value")
[SQL: INSERT INTO ticket_sale (trans_date, event_id, event_name, event_date, event_type, event_city, customer_id, price, num_tickets) VALUES (%(trans_date)s, %(event_id)s, %(event_name)s, %(event_date)s, %(event_type)s, %(event_city)s, %(customer_id)s, %(price)s, %(num_tickets)s)]
[parameters: {'trans_date': None, 'event_id': None, 'event_name': None, 'event_date': None, 'event_type': None, 'event_city': None, 'customer_id': None, 'price': None, 'num_tickets': None}]
(Background on this error at: https://sqlalche.me/e/14/e3q8)
Traceback (most recent call last):
  File "C:\ProgramData\Anaconda3\envs\bank\lib\site-packages\sqlalchemy\engine\base.py", line 1802, in _execute_context
    self.dialect.do_execute(
  File "C:\ProgramData\Anaconda3\envs\bank\lib\site-packages\sqlalchemy\engine\default.py", line 719, in do_execute
    cursor.execute(statement, parameters)
  File "C:\ProgramData\Anaconda3\envs\bank\lib\site-packages\pymysql\cursors.py", line 148, in execute
    result = self._query(query)
  File "C:\ProgramData\Anaconda3\envs\bank\lib\site-packages\pymysql\cursors.py", line 310, in _query
    conn.query(q)
  File "C:\ProgramData\Anaconda3\envs\bank\lib\site-packages\pymysql\connections.py", line 548, in query
    self._affected_rows = self._read_query_result(unbuffered=unbuffered)
  File "C:\ProgramData\Anaconda3\envs\bank\lib\site-packages\pymysql\connections.py", line 775, in _read_query_result
    result.read()
  File "C:\ProgramData\Anaconda3\envs\bank\lib\site-packages\pymysql\connections.py", line 1156, in read
    first_packet = self.connection._read_packet()
  File "C:\ProgramData\Anaconda3\envs\bank\lib\site-packages\pymysql\connections.py", line 725, in _read_packet
    packet.raise_for_error()
  File "C:\ProgramData\Anaconda3\envs\bank\lib\site-packages\pymysql\protocol.py", line 221, in raise_for_error
    err.raise_mysql_exception(self._data)
  File "C:\ProgramData\Anaconda3\envs\bank\lib\site-packages\pymysql\err.py", line 143, in raise_mysql_exception
    raise errorclass(errno, errval)
pymysql.err.OperationalError: (1364, "Field 'ticket_id' doesn't have a default value")

The above exception was the direct cause of the following exception:

Traceback (most recent call last):
  File "C:\Users\huang\OneDrive\14-code\bank\database.py", line 89, in new_rec_in_db
    session.commit()
  File "C:\ProgramData\Anaconda3\envs\bank\lib\site-packages\sqlalchemy\orm\session.py", line 1428, in commit
    self._transaction.commit(_to_root=self.future)
  File "C:\ProgramData\Anaconda3\envs\bank\lib\site-packages\sqlalchemy\orm\session.py", line 829, in commit
    self._prepare_impl()
  File "C:\ProgramData\Anaconda3\envs\bank\lib\site-packages\sqlalchemy\orm\session.py", line 808, in _prepare_impl
    self.session.flush()
  File "C:\ProgramData\Anaconda3\envs\bank\lib\site-packages\sqlalchemy\orm\session.py", line 3345, in flush
    self._flush(objects)
  File "C:\ProgramData\Anaconda3\envs\bank\lib\site-packages\sqlalchemy\orm\session.py", line 3485, in _flush
    transaction.rollback(_capture_exception=True)
  File "C:\ProgramData\Anaconda3\envs\bank\lib\site-packages\sqlalchemy\util\langhelpers.py", line 70, in __exit__
    compat.raise_(
  File "C:\ProgramData\Anaconda3\envs\bank\lib\site-packages\sqlalchemy\util\compat.py", line 207, in raise_
    raise exception
  File "C:\ProgramData\Anaconda3\envs\bank\lib\site-packages\sqlalchemy\orm\session.py", line 3445, in _flush
    flush_context.execute()
  File "C:\ProgramData\Anaconda3\envs\bank\lib\site-packages\sqlalchemy\orm\unitofwork.py", line 456, in execute
    rec.execute(self)
  File "C:\ProgramData\Anaconda3\envs\bank\lib\site-packages\sqlalchemy\orm\unitofwork.py", line 630, in execute
    util.preloaded.orm_persistence.save_obj(
  File "C:\ProgramData\Anaconda3\envs\bank\lib\site-packages\sqlalchemy\orm\persistence.py", line 244, in save_obj
    _emit_insert_statements(
  File "C:\ProgramData\Anaconda3\envs\bank\lib\site-packages\sqlalchemy\orm\persistence.py", line 1221, in _emit_insert_statements
    result = connection._execute_20(
  File "C:\ProgramData\Anaconda3\envs\bank\lib\site-packages\sqlalchemy\engine\base.py", line 1614, in _execute_20
    return meth(self, args_10style, kwargs_10style, execution_options)
  File "C:\ProgramData\Anaconda3\envs\bank\lib\site-packages\sqlalchemy\sql\elements.py", line 325, in _execute_on_connection
    return connection._execute_clauseelement(
  File "C:\ProgramData\Anaconda3\envs\bank\lib\site-packages\sqlalchemy\engine\base.py", line 1481, in _execute_clauseelement
    ret = self._execute_context(
  File "C:\ProgramData\Anaconda3\envs\bank\lib\site-packages\sqlalchemy\engine\base.py", line 1845, in _execute_context
    self._handle_dbapi_exception(
  File "C:\ProgramData\Anaconda3\envs\bank\lib\site-packages\sqlalchemy\engine\base.py", line 2026, in _handle_dbapi_exception
    util.raise_(
  File "C:\ProgramData\Anaconda3\envs\bank\lib\site-packages\sqlalchemy\util\compat.py", line 207, in raise_
    raise exception
  File "C:\ProgramData\Anaconda3\envs\bank\lib\site-packages\sqlalchemy\engine\base.py", line 1802, in _execute_context
    self.dialect.do_execute(
  File "C:\ProgramData\Anaconda3\envs\bank\lib\site-packages\sqlalchemy\engine\default.py", line 719, in do_execute
    cursor.execute(statement, parameters)
  File "C:\ProgramData\Anaconda3\envs\bank\lib\site-packages\pymysql\cursors.py", line 148, in execute
    result = self._query(query)
  File "C:\ProgramData\Anaconda3\envs\bank\lib\site-packages\pymysql\cursors.py", line 310, in _query
    conn.query(q)
  File "C:\ProgramData\Anaconda3\envs\bank\lib\site-packages\pymysql\connections.py", line 548, in query
    self._affected_rows = self._read_query_result(unbuffered=unbuffered)
  File "C:\ProgramData\Anaconda3\envs\bank\lib\site-packages\pymysql\connections.py", line 775, in _read_query_result
    result.read()
  File "C:\ProgramData\Anaconda3\envs\bank\lib\site-packages\pymysql\connections.py", line 1156, in read
    first_packet = self.connection._read_packet()
  File "C:\ProgramData\Anaconda3\envs\bank\lib\site-packages\pymysql\connections.py", line 725, in _read_packet
    packet.raise_for_error()
  File "C:\ProgramData\Anaconda3\envs\bank\lib\site-packages\pymysql\protocol.py", line 221, in raise_for_error
    err.raise_mysql_exception(self._data)
  File "C:\ProgramData\Anaconda3\envs\bank\lib\site-packages\pymysql\err.py", line 143, in raise_mysql_exception
    raise errorclass(errno, errval)
sqlalchemy.exc.OperationalError: (pymysql.err.OperationalError) (1364, "Field 'ticket_id' doesn't have a default value")
[SQL: INSERT INTO ticket_sale (trans_date, event_id, event_name, event_date, event_type, event_city, customer_id, price, num_tickets) VALUES (%(trans_date)s, %(event_id)s, %(event_name)s, %(event_date)s, %(event_type)s, %(event_city)s, %(customer_id)s, %(price)s, %(num_tickets)s)]
[parameters: {'trans_date': None, 'event_id': None, 'event_name': None, 'event_date': None, 'event_type': None, 'event_city': None, 'customer_id': None, 'price': None, 'num_tickets': None}]
(Background on this error at: https://sqlalche.me/e/14/e3q8)
2022-02-02 18:26:38,596:utility.py:logger_expt:ERROR:(pymysql.err.OperationalError) (1364, "Field 'ticket_id' doesn't have a default value")
[SQL: INSERT INTO ticket_sale (trans_date, event_id, event_name, event_date, event_type, event_city, customer_id, price, num_tickets) VALUES (%(trans_date)s, %(event_id)s, %(event_name)s, %(event_date)s, %(event_type)s, %(event_city)s, %(customer_id)s, %(price)s, %(num_tickets)s)]
[parameters: {'trans_date': None, 'event_id': None, 'event_name': None, 'event_date': None, 'event_type': None, 'event_city': None, 'customer_id': None, 'price': None, 'num_tickets': None}]
(Background on this error at: https://sqlalche.me/e/14/e3q8)
Traceback (most recent call last):
  File "C:\ProgramData\Anaconda3\envs\bank\lib\site-packages\sqlalchemy\engine\base.py", line 1802, in _execute_context
    self.dialect.do_execute(
  File "C:\ProgramData\Anaconda3\envs\bank\lib\site-packages\sqlalchemy\engine\default.py", line 719, in do_execute
    cursor.execute(statement, parameters)
  File "C:\ProgramData\Anaconda3\envs\bank\lib\site-packages\pymysql\cursors.py", line 148, in execute
    result = self._query(query)
  File "C:\ProgramData\Anaconda3\envs\bank\lib\site-packages\pymysql\cursors.py", line 310, in _query
    conn.query(q)
  File "C:\ProgramData\Anaconda3\envs\bank\lib\site-packages\pymysql\connections.py", line 548, in query
    self._affected_rows = self._read_query_result(unbuffered=unbuffered)
  File "C:\ProgramData\Anaconda3\envs\bank\lib\site-packages\pymysql\connections.py", line 775, in _read_query_result
    result.read()
  File "C:\ProgramData\Anaconda3\envs\bank\lib\site-packages\pymysql\connections.py", line 1156, in read
    first_packet = self.connection._read_packet()
  File "C:\ProgramData\Anaconda3\envs\bank\lib\site-packages\pymysql\connections.py", line 725, in _read_packet
    packet.raise_for_error()
  File "C:\ProgramData\Anaconda3\envs\bank\lib\site-packages\pymysql\protocol.py", line 221, in raise_for_error
    err.raise_mysql_exception(self._data)
  File "C:\ProgramData\Anaconda3\envs\bank\lib\site-packages\pymysql\err.py", line 143, in raise_mysql_exception
    raise errorclass(errno, errval)
pymysql.err.OperationalError: (1364, "Field 'ticket_id' doesn't have a default value")

The above exception was the direct cause of the following exception:

Traceback (most recent call last):
  File "C:\Users\huang\OneDrive\14-code\bank\database.py", line 89, in new_rec_in_db
    session.commit()
  File "C:\ProgramData\Anaconda3\envs\bank\lib\site-packages\sqlalchemy\orm\session.py", line 1428, in commit
    self._transaction.commit(_to_root=self.future)
  File "C:\ProgramData\Anaconda3\envs\bank\lib\site-packages\sqlalchemy\orm\session.py", line 829, in commit
    self._prepare_impl()
  File "C:\ProgramData\Anaconda3\envs\bank\lib\site-packages\sqlalchemy\orm\session.py", line 808, in _prepare_impl
    self.session.flush()
  File "C:\ProgramData\Anaconda3\envs\bank\lib\site-packages\sqlalchemy\orm\session.py", line 3345, in flush
    self._flush(objects)
  File "C:\ProgramData\Anaconda3\envs\bank\lib\site-packages\sqlalchemy\orm\session.py", line 3485, in _flush
    transaction.rollback(_capture_exception=True)
  File "C:\ProgramData\Anaconda3\envs\bank\lib\site-packages\sqlalchemy\util\langhelpers.py", line 70, in __exit__
    compat.raise_(
  File "C:\ProgramData\Anaconda3\envs\bank\lib\site-packages\sqlalchemy\util\compat.py", line 207, in raise_
    raise exception
  File "C:\ProgramData\Anaconda3\envs\bank\lib\site-packages\sqlalchemy\orm\session.py", line 3445, in _flush
    flush_context.execute()
  File "C:\ProgramData\Anaconda3\envs\bank\lib\site-packages\sqlalchemy\orm\unitofwork.py", line 456, in execute
    rec.execute(self)
  File "C:\ProgramData\Anaconda3\envs\bank\lib\site-packages\sqlalchemy\orm\unitofwork.py", line 630, in execute
    util.preloaded.orm_persistence.save_obj(
  File "C:\ProgramData\Anaconda3\envs\bank\lib\site-packages\sqlalchemy\orm\persistence.py", line 244, in save_obj
    _emit_insert_statements(
  File "C:\ProgramData\Anaconda3\envs\bank\lib\site-packages\sqlalchemy\orm\persistence.py", line 1221, in _emit_insert_statements
    result = connection._execute_20(
  File "C:\ProgramData\Anaconda3\envs\bank\lib\site-packages\sqlalchemy\engine\base.py", line 1614, in _execute_20
    return meth(self, args_10style, kwargs_10style, execution_options)
  File "C:\ProgramData\Anaconda3\envs\bank\lib\site-packages\sqlalchemy\sql\elements.py", line 325, in _execute_on_connection
    return connection._execute_clauseelement(
  File "C:\ProgramData\Anaconda3\envs\bank\lib\site-packages\sqlalchemy\engine\base.py", line 1481, in _execute_clauseelement
    ret = self._execute_context(
  File "C:\ProgramData\Anaconda3\envs\bank\lib\site-packages\sqlalchemy\engine\base.py", line 1845, in _execute_context
    self._handle_dbapi_exception(
  File "C:\ProgramData\Anaconda3\envs\bank\lib\site-packages\sqlalchemy\engine\base.py", line 2026, in _handle_dbapi_exception
    util.raise_(
  File "C:\ProgramData\Anaconda3\envs\bank\lib\site-packages\sqlalchemy\util\compat.py", line 207, in raise_
    raise exception
  File "C:\ProgramData\Anaconda3\envs\bank\lib\site-packages\sqlalchemy\engine\base.py", line 1802, in _execute_context
    self.dialect.do_execute(
  File "C:\ProgramData\Anaconda3\envs\bank\lib\site-packages\sqlalchemy\engine\default.py", line 719, in do_execute
    cursor.execute(statement, parameters)
  File "C:\ProgramData\Anaconda3\envs\bank\lib\site-packages\pymysql\cursors.py", line 148, in execute
    result = self._query(query)
  File "C:\ProgramData\Anaconda3\envs\bank\lib\site-packages\pymysql\cursors.py", line 310, in _query
    conn.query(q)
  File "C:\ProgramData\Anaconda3\envs\bank\lib\site-packages\pymysql\connections.py", line 548, in query
    self._affected_rows = self._read_query_result(unbuffered=unbuffered)
  File "C:\ProgramData\Anaconda3\envs\bank\lib\site-packages\pymysql\connections.py", line 775, in _read_query_result
    result.read()
  File "C:\ProgramData\Anaconda3\envs\bank\lib\site-packages\pymysql\connections.py", line 1156, in read
    first_packet = self.connection._read_packet()
  File "C:\ProgramData\Anaconda3\envs\bank\lib\site-packages\pymysql\connections.py", line 725, in _read_packet
    packet.raise_for_error()
  File "C:\ProgramData\Anaconda3\envs\bank\lib\site-packages\pymysql\protocol.py", line 221, in raise_for_error
    err.raise_mysql_exception(self._data)
  File "C:\ProgramData\Anaconda3\envs\bank\lib\site-packages\pymysql\err.py", line 143, in raise_mysql_exception
    raise errorclass(errno, errval)
sqlalchemy.exc.OperationalError: (pymysql.err.OperationalError) (1364, "Field 'ticket_id' doesn't have a default value")
[SQL: INSERT INTO ticket_sale (trans_date, event_id, event_name, event_date, event_type, event_city, customer_id, price, num_tickets) VALUES (%(trans_date)s, %(event_id)s, %(event_name)s, %(event_date)s, %(event_type)s, %(event_city)s, %(customer_id)s, %(price)s, %(num_tickets)s)]
[parameters: {'trans_date': None, 'event_id': None, 'event_name': None, 'event_date': None, 'event_type': None, 'event_city': None, 'customer_id': None, 'price': None, 'num_tickets': None}]
(Background on this error at: https://sqlalche.me/e/14/e3q8)
2022-02-03 06:21:19,298:utility.py:logger_expt:ERROR:(pymysql.err.IntegrityError) (1062, "Duplicate entry '3' for key 'ticket_sale.PRIMARY'")
[SQL: INSERT INTO ticket_sale (ticket_id, trans_date, event_id, event_name, event_date, event_type, event_city, customer_id, price, num_tickets) VALUES (%(ticket_id)s, %(trans_date)s, %(event_id)s, %(event_name)s, %(event_date)s, %(event_type)s, %(event_city)s, %(customer_id)s, %(price)s, %(num_tickets)s)]
[parameters: {'ticket_id': 3, 'trans_date': None, 'event_id': 39, 'event_name': None, 'event_date': None, 'event_type': None, 'event_city': None, 'customer_id': None, 'price': 300, 'num_tickets': None}]
(Background on this error at: https://sqlalche.me/e/14/gkpj)
Traceback (most recent call last):
  File "C:\ProgramData\Anaconda3\envs\bank\lib\site-packages\sqlalchemy\engine\base.py", line 1802, in _execute_context
    self.dialect.do_execute(
  File "C:\ProgramData\Anaconda3\envs\bank\lib\site-packages\sqlalchemy\engine\default.py", line 719, in do_execute
    cursor.execute(statement, parameters)
  File "C:\ProgramData\Anaconda3\envs\bank\lib\site-packages\pymysql\cursors.py", line 148, in execute
    result = self._query(query)
  File "C:\ProgramData\Anaconda3\envs\bank\lib\site-packages\pymysql\cursors.py", line 310, in _query
    conn.query(q)
  File "C:\ProgramData\Anaconda3\envs\bank\lib\site-packages\pymysql\connections.py", line 548, in query
    self._affected_rows = self._read_query_result(unbuffered=unbuffered)
  File "C:\ProgramData\Anaconda3\envs\bank\lib\site-packages\pymysql\connections.py", line 775, in _read_query_result
    result.read()
  File "C:\ProgramData\Anaconda3\envs\bank\lib\site-packages\pymysql\connections.py", line 1156, in read
    first_packet = self.connection._read_packet()
  File "C:\ProgramData\Anaconda3\envs\bank\lib\site-packages\pymysql\connections.py", line 725, in _read_packet
    packet.raise_for_error()
  File "C:\ProgramData\Anaconda3\envs\bank\lib\site-packages\pymysql\protocol.py", line 221, in raise_for_error
    err.raise_mysql_exception(self._data)
  File "C:\ProgramData\Anaconda3\envs\bank\lib\site-packages\pymysql\err.py", line 143, in raise_mysql_exception
    raise errorclass(errno, errval)
pymysql.err.IntegrityError: (1062, "Duplicate entry '3' for key 'ticket_sale.PRIMARY'")

The above exception was the direct cause of the following exception:

Traceback (most recent call last):
  File "C:\Users\huang\OneDrive\14-code\bank\database.py", line 89, in new_rec_in_db
    session.commit()
  File "C:\ProgramData\Anaconda3\envs\bank\lib\site-packages\sqlalchemy\orm\session.py", line 1428, in commit
    self._transaction.commit(_to_root=self.future)
  File "C:\ProgramData\Anaconda3\envs\bank\lib\site-packages\sqlalchemy\orm\session.py", line 829, in commit
    self._prepare_impl()
  File "C:\ProgramData\Anaconda3\envs\bank\lib\site-packages\sqlalchemy\orm\session.py", line 808, in _prepare_impl
    self.session.flush()
  File "C:\ProgramData\Anaconda3\envs\bank\lib\site-packages\sqlalchemy\orm\session.py", line 3345, in flush
    self._flush(objects)
  File "C:\ProgramData\Anaconda3\envs\bank\lib\site-packages\sqlalchemy\orm\session.py", line 3485, in _flush
    transaction.rollback(_capture_exception=True)
  File "C:\ProgramData\Anaconda3\envs\bank\lib\site-packages\sqlalchemy\util\langhelpers.py", line 70, in __exit__
    compat.raise_(
  File "C:\ProgramData\Anaconda3\envs\bank\lib\site-packages\sqlalchemy\util\compat.py", line 207, in raise_
    raise exception
  File "C:\ProgramData\Anaconda3\envs\bank\lib\site-packages\sqlalchemy\orm\session.py", line 3445, in _flush
    flush_context.execute()
  File "C:\ProgramData\Anaconda3\envs\bank\lib\site-packages\sqlalchemy\orm\unitofwork.py", line 456, in execute
    rec.execute(self)
  File "C:\ProgramData\Anaconda3\envs\bank\lib\site-packages\sqlalchemy\orm\unitofwork.py", line 630, in execute
    util.preloaded.orm_persistence.save_obj(
  File "C:\ProgramData\Anaconda3\envs\bank\lib\site-packages\sqlalchemy\orm\persistence.py", line 244, in save_obj
    _emit_insert_statements(
  File "C:\ProgramData\Anaconda3\envs\bank\lib\site-packages\sqlalchemy\orm\persistence.py", line 1096, in _emit_insert_statements
    c = connection._execute_20(
  File "C:\ProgramData\Anaconda3\envs\bank\lib\site-packages\sqlalchemy\engine\base.py", line 1614, in _execute_20
    return meth(self, args_10style, kwargs_10style, execution_options)
  File "C:\ProgramData\Anaconda3\envs\bank\lib\site-packages\sqlalchemy\sql\elements.py", line 325, in _execute_on_connection
    return connection._execute_clauseelement(
  File "C:\ProgramData\Anaconda3\envs\bank\lib\site-packages\sqlalchemy\engine\base.py", line 1481, in _execute_clauseelement
    ret = self._execute_context(
  File "C:\ProgramData\Anaconda3\envs\bank\lib\site-packages\sqlalchemy\engine\base.py", line 1845, in _execute_context
    self._handle_dbapi_exception(
  File "C:\ProgramData\Anaconda3\envs\bank\lib\site-packages\sqlalchemy\engine\base.py", line 2026, in _handle_dbapi_exception
    util.raise_(
  File "C:\ProgramData\Anaconda3\envs\bank\lib\site-packages\sqlalchemy\util\compat.py", line 207, in raise_
    raise exception
  File "C:\ProgramData\Anaconda3\envs\bank\lib\site-packages\sqlalchemy\engine\base.py", line 1802, in _execute_context
    self.dialect.do_execute(
  File "C:\ProgramData\Anaconda3\envs\bank\lib\site-packages\sqlalchemy\engine\default.py", line 719, in do_execute
    cursor.execute(statement, parameters)
  File "C:\ProgramData\Anaconda3\envs\bank\lib\site-packages\pymysql\cursors.py", line 148, in execute
    result = self._query(query)
  File "C:\ProgramData\Anaconda3\envs\bank\lib\site-packages\pymysql\cursors.py", line 310, in _query
    conn.query(q)
  File "C:\ProgramData\Anaconda3\envs\bank\lib\site-packages\pymysql\connections.py", line 548, in query
    self._affected_rows = self._read_query_result(unbuffered=unbuffered)
  File "C:\ProgramData\Anaconda3\envs\bank\lib\site-packages\pymysql\connections.py", line 775, in _read_query_result
    result.read()
  File "C:\ProgramData\Anaconda3\envs\bank\lib\site-packages\pymysql\connections.py", line 1156, in read
    first_packet = self.connection._read_packet()
  File "C:\ProgramData\Anaconda3\envs\bank\lib\site-packages\pymysql\connections.py", line 725, in _read_packet
    packet.raise_for_error()
  File "C:\ProgramData\Anaconda3\envs\bank\lib\site-packages\pymysql\protocol.py", line 221, in raise_for_error
    err.raise_mysql_exception(self._data)
  File "C:\ProgramData\Anaconda3\envs\bank\lib\site-packages\pymysql\err.py", line 143, in raise_mysql_exception
    raise errorclass(errno, errval)
sqlalchemy.exc.IntegrityError: (pymysql.err.IntegrityError) (1062, "Duplicate entry '3' for key 'ticket_sale.PRIMARY'")
[SQL: INSERT INTO ticket_sale (ticket_id, trans_date, event_id, event_name, event_date, event_type, event_city, customer_id, price, num_tickets) VALUES (%(ticket_id)s, %(trans_date)s, %(event_id)s, %(event_name)s, %(event_date)s, %(event_type)s, %(event_city)s, %(customer_id)s, %(price)s, %(num_tickets)s)]
[parameters: {'ticket_id': 3, 'trans_date': None, 'event_id': 39, 'event_name': None, 'event_date': None, 'event_type': None, 'event_city': None, 'customer_id': None, 'price': 300, 'num_tickets': None}]
(Background on this error at: https://sqlalche.me/e/14/gkpj)
2022-02-04 16:25:38,477:utility.py:logger_expt:ERROR:Multiple rows were found when exactly one was required
Traceback (most recent call last):
  File "C:\Users\huang\OneDrive\14-code\bank\customer.py", line 61, in f_customer_not_exist
    rec = session.query(Customer).filter(Customer.name == p_name).filter(or_(Customer.address == p_addr,
  File "C:\ProgramData\Anaconda3\lib\site-packages\sqlalchemy\orm\query.py", line 2782, in one
    return self._iter().one()
  File "C:\ProgramData\Anaconda3\lib\site-packages\sqlalchemy\engine\result.py", line 1380, in one
    return self._only_one_row(True, True, False)
  File "C:\ProgramData\Anaconda3\lib\site-packages\sqlalchemy\engine\result.py", line 620, in _only_one_row
    raise exc.MultipleResultsFound(
sqlalchemy.exc.MultipleResultsFound: Multiple rows were found when exactly one was required
2022-02-04 16:25:47,783:utility.py:logger_expt:ERROR:Multiple rows were found when exactly one was required
Traceback (most recent call last):
  File "C:\Users\huang\OneDrive\14-code\bank\customer.py", line 61, in f_customer_not_exist
    rec = session.query(Customer).filter(Customer.name == p_name).filter(or_(Customer.address == p_addr,
  File "C:\ProgramData\Anaconda3\lib\site-packages\sqlalchemy\orm\query.py", line 2782, in one
    return self._iter().one()
  File "C:\ProgramData\Anaconda3\lib\site-packages\sqlalchemy\engine\result.py", line 1380, in one
    return self._only_one_row(True, True, False)
  File "C:\ProgramData\Anaconda3\lib\site-packages\sqlalchemy\engine\result.py", line 620, in _only_one_row
    raise exc.MultipleResultsFound(
sqlalchemy.exc.MultipleResultsFound: Multiple rows were found when exactly one was required
2022-02-04 16:26:46,687:utility.py:logger_expt:ERROR:Multiple rows were found when exactly one was required
Traceback (most recent call last):
  File "C:\Users\huang\OneDrive\14-code\bank\customer.py", line 61, in f_customer_not_exist
    rec = session.query(Customer).filter(Customer.name == p_name).filter(or_(Customer.address == p_addr,
  File "C:\ProgramData\Anaconda3\lib\site-packages\sqlalchemy\orm\query.py", line 2782, in one
    return self._iter().one()
  File "C:\ProgramData\Anaconda3\lib\site-packages\sqlalchemy\engine\result.py", line 1380, in one
    return self._only_one_row(True, True, False)
  File "C:\ProgramData\Anaconda3\lib\site-packages\sqlalchemy\engine\result.py", line 620, in _only_one_row
    raise exc.MultipleResultsFound(
sqlalchemy.exc.MultipleResultsFound: Multiple rows were found when exactly one was required
2022-02-04 16:57:29,859:utility.py:logger_expt:ERROR:Multiple rows were found when exactly one was required
Traceback (most recent call last):
  File "C:/Users/huang/OneDrive/14-code/bank/customer.py", line 61, in get_by_name_addr
    rec = session.query(Customer).filter(Customer.name == p_name).filter(or_(Customer.address == p_addr,
  File "C:\ProgramData\Anaconda3\envs\bank\lib\site-packages\sqlalchemy\orm\query.py", line 2879, in scalar
    ret = self.one()
  File "C:\ProgramData\Anaconda3\envs\bank\lib\site-packages\sqlalchemy\orm\query.py", line 2856, in one
    return self._iter().one()
  File "C:\ProgramData\Anaconda3\envs\bank\lib\site-packages\sqlalchemy\engine\result.py", line 1407, in one
    return self._only_one_row(
  File "C:\ProgramData\Anaconda3\envs\bank\lib\site-packages\sqlalchemy\engine\result.py", line 613, in _only_one_row
    raise exc.MultipleResultsFound(
sqlalchemy.exc.MultipleResultsFound: Multiple rows were found when exactly one was required
2022-02-04 16:57:38,889:utility.py:logger_expt:ERROR:Multiple rows were found when exactly one was required
Traceback (most recent call last):
  File "C:/Users/huang/OneDrive/14-code/bank/customer.py", line 61, in get_by_name_addr
    rec = session.query(Customer).filter(Customer.name == p_name).filter(or_(Customer.address == p_addr,
  File "C:\ProgramData\Anaconda3\envs\bank\lib\site-packages\sqlalchemy\orm\query.py", line 2879, in scalar
    ret = self.one()
  File "C:\ProgramData\Anaconda3\envs\bank\lib\site-packages\sqlalchemy\orm\query.py", line 2856, in one
    return self._iter().one()
  File "C:\ProgramData\Anaconda3\envs\bank\lib\site-packages\sqlalchemy\engine\result.py", line 1407, in one
    return self._only_one_row(
  File "C:\ProgramData\Anaconda3\envs\bank\lib\site-packages\sqlalchemy\engine\result.py", line 613, in _only_one_row
    raise exc.MultipleResultsFound(
sqlalchemy.exc.MultipleResultsFound: Multiple rows were found when exactly one was required
2022-02-04 17:01:37,709:utility.py:logger_expt:ERROR:Multiple rows were found when exactly one was required
Traceback (most recent call last):
  File "C:\Users\huang\OneDrive\14-code\bank\customer.py", line 61, in get_by_name_addr
    rec = session.query(Customer).filter(Customer.name == p_name).filter(or_(Customer.address == p_addr,
  File "C:\ProgramData\Anaconda3\lib\site-packages\sqlalchemy\orm\query.py", line 2805, in scalar
    ret = self.one()
  File "C:\ProgramData\Anaconda3\lib\site-packages\sqlalchemy\orm\query.py", line 2782, in one
    return self._iter().one()
  File "C:\ProgramData\Anaconda3\lib\site-packages\sqlalchemy\engine\result.py", line 1380, in one
    return self._only_one_row(True, True, False)
  File "C:\ProgramData\Anaconda3\lib\site-packages\sqlalchemy\engine\result.py", line 620, in _only_one_row
    raise exc.MultipleResultsFound(
sqlalchemy.exc.MultipleResultsFound: Multiple rows were found when exactly one was required
2022-02-04 21:54:42,120:utility.py:logger_expt:ERROR:(pymysql.err.DataError) (1264, "Out of range value for column 'card_no' at row 1")
[SQL: INSERT INTO creditcard (card_no, exp_date, customer_id, customer_name, credit_limit, employee_id, cr_date) VALUES (%(card_no)s, %(exp_date)s, %(customer_id)s, %(customer_name)s, %(credit_limit)s, %(employee_id)s, %(cr_date)s)]
[parameters: {'card_no': 8880000000000565, 'exp_date': datetime.datetime(2023, 2, 4, 21, 54, 42, 105150), 'customer_id': 100, 'customer_name': None, 'credit_limit': 1000, 'employee_id': None, 'cr_date': datetime.datetime(2022, 2, 4, 21, 54, 42, 105150)}]
(Background on this error at: https://sqlalche.me/e/14/9h9h)
Traceback (most recent call last):
  File "C:\ProgramData\Anaconda3\envs\bank\lib\site-packages\sqlalchemy\engine\base.py", line 1802, in _execute_context
    self.dialect.do_execute(
  File "C:\ProgramData\Anaconda3\envs\bank\lib\site-packages\sqlalchemy\engine\default.py", line 719, in do_execute
    cursor.execute(statement, parameters)
  File "C:\ProgramData\Anaconda3\envs\bank\lib\site-packages\pymysql\cursors.py", line 148, in execute
    result = self._query(query)
  File "C:\ProgramData\Anaconda3\envs\bank\lib\site-packages\pymysql\cursors.py", line 310, in _query
    conn.query(q)
  File "C:\ProgramData\Anaconda3\envs\bank\lib\site-packages\pymysql\connections.py", line 548, in query
    self._affected_rows = self._read_query_result(unbuffered=unbuffered)
  File "C:\ProgramData\Anaconda3\envs\bank\lib\site-packages\pymysql\connections.py", line 775, in _read_query_result
    result.read()
  File "C:\ProgramData\Anaconda3\envs\bank\lib\site-packages\pymysql\connections.py", line 1156, in read
    first_packet = self.connection._read_packet()
  File "C:\ProgramData\Anaconda3\envs\bank\lib\site-packages\pymysql\connections.py", line 725, in _read_packet
    packet.raise_for_error()
  File "C:\ProgramData\Anaconda3\envs\bank\lib\site-packages\pymysql\protocol.py", line 221, in raise_for_error
    err.raise_mysql_exception(self._data)
  File "C:\ProgramData\Anaconda3\envs\bank\lib\site-packages\pymysql\err.py", line 143, in raise_mysql_exception
    raise errorclass(errno, errval)
pymysql.err.DataError: (1264, "Out of range value for column 'card_no' at row 1")

The above exception was the direct cause of the following exception:

Traceback (most recent call last):
  File "C:\Users\huang\OneDrive\14-code\bank\database.py", line 89, in new_rec_in_db
    session.commit()
  File "C:\ProgramData\Anaconda3\envs\bank\lib\site-packages\sqlalchemy\orm\session.py", line 1428, in commit
    self._transaction.commit(_to_root=self.future)
  File "C:\ProgramData\Anaconda3\envs\bank\lib\site-packages\sqlalchemy\orm\session.py", line 829, in commit
    self._prepare_impl()
  File "C:\ProgramData\Anaconda3\envs\bank\lib\site-packages\sqlalchemy\orm\session.py", line 808, in _prepare_impl
    self.session.flush()
  File "C:\ProgramData\Anaconda3\envs\bank\lib\site-packages\sqlalchemy\orm\session.py", line 3345, in flush
    self._flush(objects)
  File "C:\ProgramData\Anaconda3\envs\bank\lib\site-packages\sqlalchemy\orm\session.py", line 3485, in _flush
    transaction.rollback(_capture_exception=True)
  File "C:\ProgramData\Anaconda3\envs\bank\lib\site-packages\sqlalchemy\util\langhelpers.py", line 70, in __exit__
    compat.raise_(
  File "C:\ProgramData\Anaconda3\envs\bank\lib\site-packages\sqlalchemy\util\compat.py", line 207, in raise_
    raise exception
  File "C:\ProgramData\Anaconda3\envs\bank\lib\site-packages\sqlalchemy\orm\session.py", line 3445, in _flush
    flush_context.execute()
  File "C:\ProgramData\Anaconda3\envs\bank\lib\site-packages\sqlalchemy\orm\unitofwork.py", line 456, in execute
    rec.execute(self)
  File "C:\ProgramData\Anaconda3\envs\bank\lib\site-packages\sqlalchemy\orm\unitofwork.py", line 630, in execute
    util.preloaded.orm_persistence.save_obj(
  File "C:\ProgramData\Anaconda3\envs\bank\lib\site-packages\sqlalchemy\orm\persistence.py", line 244, in save_obj
    _emit_insert_statements(
  File "C:\ProgramData\Anaconda3\envs\bank\lib\site-packages\sqlalchemy\orm\persistence.py", line 1221, in _emit_insert_statements
    result = connection._execute_20(
  File "C:\ProgramData\Anaconda3\envs\bank\lib\site-packages\sqlalchemy\engine\base.py", line 1614, in _execute_20
    return meth(self, args_10style, kwargs_10style, execution_options)
  File "C:\ProgramData\Anaconda3\envs\bank\lib\site-packages\sqlalchemy\sql\elements.py", line 325, in _execute_on_connection
    return connection._execute_clauseelement(
  File "C:\ProgramData\Anaconda3\envs\bank\lib\site-packages\sqlalchemy\engine\base.py", line 1481, in _execute_clauseelement
    ret = self._execute_context(
  File "C:\ProgramData\Anaconda3\envs\bank\lib\site-packages\sqlalchemy\engine\base.py", line 1845, in _execute_context
    self._handle_dbapi_exception(
  File "C:\ProgramData\Anaconda3\envs\bank\lib\site-packages\sqlalchemy\engine\base.py", line 2026, in _handle_dbapi_exception
    util.raise_(
  File "C:\ProgramData\Anaconda3\envs\bank\lib\site-packages\sqlalchemy\util\compat.py", line 207, in raise_
    raise exception
  File "C:\ProgramData\Anaconda3\envs\bank\lib\site-packages\sqlalchemy\engine\base.py", line 1802, in _execute_context
    self.dialect.do_execute(
  File "C:\ProgramData\Anaconda3\envs\bank\lib\site-packages\sqlalchemy\engine\default.py", line 719, in do_execute
    cursor.execute(statement, parameters)
  File "C:\ProgramData\Anaconda3\envs\bank\lib\site-packages\pymysql\cursors.py", line 148, in execute
    result = self._query(query)
  File "C:\ProgramData\Anaconda3\envs\bank\lib\site-packages\pymysql\cursors.py", line 310, in _query
    conn.query(q)
  File "C:\ProgramData\Anaconda3\envs\bank\lib\site-packages\pymysql\connections.py", line 548, in query
    self._affected_rows = self._read_query_result(unbuffered=unbuffered)
  File "C:\ProgramData\Anaconda3\envs\bank\lib\site-packages\pymysql\connections.py", line 775, in _read_query_result
    result.read()
  File "C:\ProgramData\Anaconda3\envs\bank\lib\site-packages\pymysql\connections.py", line 1156, in read
    first_packet = self.connection._read_packet()
  File "C:\ProgramData\Anaconda3\envs\bank\lib\site-packages\pymysql\connections.py", line 725, in _read_packet
    packet.raise_for_error()
  File "C:\ProgramData\Anaconda3\envs\bank\lib\site-packages\pymysql\protocol.py", line 221, in raise_for_error
    err.raise_mysql_exception(self._data)
  File "C:\ProgramData\Anaconda3\envs\bank\lib\site-packages\pymysql\err.py", line 143, in raise_mysql_exception
    raise errorclass(errno, errval)
sqlalchemy.exc.DataError: (pymysql.err.DataError) (1264, "Out of range value for column 'card_no' at row 1")
[SQL: INSERT INTO creditcard (card_no, exp_date, customer_id, customer_name, credit_limit, employee_id, cr_date) VALUES (%(card_no)s, %(exp_date)s, %(customer_id)s, %(customer_name)s, %(credit_limit)s, %(employee_id)s, %(cr_date)s)]
[parameters: {'card_no': 8880000000000565, 'exp_date': datetime.datetime(2023, 2, 4, 21, 54, 42, 105150), 'customer_id': 100, 'customer_name': None, 'credit_limit': 1000, 'employee_id': None, 'cr_date': datetime.datetime(2022, 2, 4, 21, 54, 42, 105150)}]
(Background on this error at: https://sqlalche.me/e/14/9h9h)
2022-02-04 21:56:36,026:utility.py:logger_expt:ERROR:(pymysql.err.DataError) (1264, "Out of range value for column 'card_no' at row 1")
[SQL: INSERT INTO creditcard (card_no, exp_date, customer_id, customer_name, credit_limit, employee_id, cr_date) VALUES (%(card_no)s, %(exp_date)s, %(customer_id)s, %(customer_name)s, %(credit_limit)s, %(employee_id)s, %(cr_date)s)]
[parameters: {'card_no': 8800000566, 'exp_date': datetime.datetime(2023, 2, 4, 21, 56, 36, 10941), 'customer_id': 100, 'customer_name': None, 'credit_limit': 1000, 'employee_id': None, 'cr_date': datetime.datetime(2022, 2, 4, 21, 56, 36, 10941)}]
(Background on this error at: https://sqlalche.me/e/14/9h9h)
Traceback (most recent call last):
  File "C:\ProgramData\Anaconda3\envs\bank\lib\site-packages\sqlalchemy\engine\base.py", line 1802, in _execute_context
    self.dialect.do_execute(
  File "C:\ProgramData\Anaconda3\envs\bank\lib\site-packages\sqlalchemy\engine\default.py", line 719, in do_execute
    cursor.execute(statement, parameters)
  File "C:\ProgramData\Anaconda3\envs\bank\lib\site-packages\pymysql\cursors.py", line 148, in execute
    result = self._query(query)
  File "C:\ProgramData\Anaconda3\envs\bank\lib\site-packages\pymysql\cursors.py", line 310, in _query
    conn.query(q)
  File "C:\ProgramData\Anaconda3\envs\bank\lib\site-packages\pymysql\connections.py", line 548, in query
    self._affected_rows = self._read_query_result(unbuffered=unbuffered)
  File "C:\ProgramData\Anaconda3\envs\bank\lib\site-packages\pymysql\connections.py", line 775, in _read_query_result
    result.read()
  File "C:\ProgramData\Anaconda3\envs\bank\lib\site-packages\pymysql\connections.py", line 1156, in read
    first_packet = self.connection._read_packet()
  File "C:\ProgramData\Anaconda3\envs\bank\lib\site-packages\pymysql\connections.py", line 725, in _read_packet
    packet.raise_for_error()
  File "C:\ProgramData\Anaconda3\envs\bank\lib\site-packages\pymysql\protocol.py", line 221, in raise_for_error
    err.raise_mysql_exception(self._data)
  File "C:\ProgramData\Anaconda3\envs\bank\lib\site-packages\pymysql\err.py", line 143, in raise_mysql_exception
    raise errorclass(errno, errval)
pymysql.err.DataError: (1264, "Out of range value for column 'card_no' at row 1")

The above exception was the direct cause of the following exception:

Traceback (most recent call last):
  File "C:\Users\huang\OneDrive\14-code\bank\database.py", line 89, in new_rec_in_db
    session.commit()
  File "C:\ProgramData\Anaconda3\envs\bank\lib\site-packages\sqlalchemy\orm\session.py", line 1428, in commit
    self._transaction.commit(_to_root=self.future)
  File "C:\ProgramData\Anaconda3\envs\bank\lib\site-packages\sqlalchemy\orm\session.py", line 829, in commit
    self._prepare_impl()
  File "C:\ProgramData\Anaconda3\envs\bank\lib\site-packages\sqlalchemy\orm\session.py", line 808, in _prepare_impl
    self.session.flush()
  File "C:\ProgramData\Anaconda3\envs\bank\lib\site-packages\sqlalchemy\orm\session.py", line 3345, in flush
    self._flush(objects)
  File "C:\ProgramData\Anaconda3\envs\bank\lib\site-packages\sqlalchemy\orm\session.py", line 3485, in _flush
    transaction.rollback(_capture_exception=True)
  File "C:\ProgramData\Anaconda3\envs\bank\lib\site-packages\sqlalchemy\util\langhelpers.py", line 70, in __exit__
    compat.raise_(
  File "C:\ProgramData\Anaconda3\envs\bank\lib\site-packages\sqlalchemy\util\compat.py", line 207, in raise_
    raise exception
  File "C:\ProgramData\Anaconda3\envs\bank\lib\site-packages\sqlalchemy\orm\session.py", line 3445, in _flush
    flush_context.execute()
  File "C:\ProgramData\Anaconda3\envs\bank\lib\site-packages\sqlalchemy\orm\unitofwork.py", line 456, in execute
    rec.execute(self)
  File "C:\ProgramData\Anaconda3\envs\bank\lib\site-packages\sqlalchemy\orm\unitofwork.py", line 630, in execute
    util.preloaded.orm_persistence.save_obj(
  File "C:\ProgramData\Anaconda3\envs\bank\lib\site-packages\sqlalchemy\orm\persistence.py", line 244, in save_obj
    _emit_insert_statements(
  File "C:\ProgramData\Anaconda3\envs\bank\lib\site-packages\sqlalchemy\orm\persistence.py", line 1221, in _emit_insert_statements
    result = connection._execute_20(
  File "C:\ProgramData\Anaconda3\envs\bank\lib\site-packages\sqlalchemy\engine\base.py", line 1614, in _execute_20
    return meth(self, args_10style, kwargs_10style, execution_options)
  File "C:\ProgramData\Anaconda3\envs\bank\lib\site-packages\sqlalchemy\sql\elements.py", line 325, in _execute_on_connection
    return connection._execute_clauseelement(
  File "C:\ProgramData\Anaconda3\envs\bank\lib\site-packages\sqlalchemy\engine\base.py", line 1481, in _execute_clauseelement
    ret = self._execute_context(
  File "C:\ProgramData\Anaconda3\envs\bank\lib\site-packages\sqlalchemy\engine\base.py", line 1845, in _execute_context
    self._handle_dbapi_exception(
  File "C:\ProgramData\Anaconda3\envs\bank\lib\site-packages\sqlalchemy\engine\base.py", line 2026, in _handle_dbapi_exception
    util.raise_(
  File "C:\ProgramData\Anaconda3\envs\bank\lib\site-packages\sqlalchemy\util\compat.py", line 207, in raise_
    raise exception
  File "C:\ProgramData\Anaconda3\envs\bank\lib\site-packages\sqlalchemy\engine\base.py", line 1802, in _execute_context
    self.dialect.do_execute(
  File "C:\ProgramData\Anaconda3\envs\bank\lib\site-packages\sqlalchemy\engine\default.py", line 719, in do_execute
    cursor.execute(statement, parameters)
  File "C:\ProgramData\Anaconda3\envs\bank\lib\site-packages\pymysql\cursors.py", line 148, in execute
    result = self._query(query)
  File "C:\ProgramData\Anaconda3\envs\bank\lib\site-packages\pymysql\cursors.py", line 310, in _query
    conn.query(q)
  File "C:\ProgramData\Anaconda3\envs\bank\lib\site-packages\pymysql\connections.py", line 548, in query
    self._affected_rows = self._read_query_result(unbuffered=unbuffered)
  File "C:\ProgramData\Anaconda3\envs\bank\lib\site-packages\pymysql\connections.py", line 775, in _read_query_result
    result.read()
  File "C:\ProgramData\Anaconda3\envs\bank\lib\site-packages\pymysql\connections.py", line 1156, in read
    first_packet = self.connection._read_packet()
  File "C:\ProgramData\Anaconda3\envs\bank\lib\site-packages\pymysql\connections.py", line 725, in _read_packet
    packet.raise_for_error()
  File "C:\ProgramData\Anaconda3\envs\bank\lib\site-packages\pymysql\protocol.py", line 221, in raise_for_error
    err.raise_mysql_exception(self._data)
  File "C:\ProgramData\Anaconda3\envs\bank\lib\site-packages\pymysql\err.py", line 143, in raise_mysql_exception
    raise errorclass(errno, errval)
sqlalchemy.exc.DataError: (pymysql.err.DataError) (1264, "Out of range value for column 'card_no' at row 1")
[SQL: INSERT INTO creditcard (card_no, exp_date, customer_id, customer_name, credit_limit, employee_id, cr_date) VALUES (%(card_no)s, %(exp_date)s, %(customer_id)s, %(customer_name)s, %(credit_limit)s, %(employee_id)s, %(cr_date)s)]
[parameters: {'card_no': 8800000566, 'exp_date': datetime.datetime(2023, 2, 4, 21, 56, 36, 10941), 'customer_id': 100, 'customer_name': None, 'credit_limit': 1000, 'employee_id': None, 'cr_date': datetime.datetime(2022, 2, 4, 21, 56, 36, 10941)}]
(Background on this error at: https://sqlalche.me/e/14/9h9h)
2022-02-04 22:32:34,136:utility.py:logger_expt:ERROR:(pymysql.err.OperationalError) (1054, "Unknown column 'status' in 'field list'")
[SQL: INSERT INTO creditcard (customer_id, status, note, employee_id, app_date, apprv_date, card_id) VALUES (%(customer_id)s, %(status)s, %(note)s, %(employee_id)s, %(app_date)s, %(apprv_date)s, %(card_id)s)]
[parameters: {'customer_id': 100, 'status': None, 'note': None, 'employee_id': None, 'app_date': datetime.datetime(2022, 2, 4, 22, 32, 34, 89179), 'apprv_date': None, 'card_id': None}]
(Background on this error at: https://sqlalche.me/e/14/e3q8)
Traceback (most recent call last):
  File "C:\ProgramData\Anaconda3\envs\bank\lib\site-packages\sqlalchemy\engine\base.py", line 1802, in _execute_context
    self.dialect.do_execute(
  File "C:\ProgramData\Anaconda3\envs\bank\lib\site-packages\sqlalchemy\engine\default.py", line 719, in do_execute
    cursor.execute(statement, parameters)
  File "C:\ProgramData\Anaconda3\envs\bank\lib\site-packages\pymysql\cursors.py", line 148, in execute
    result = self._query(query)
  File "C:\ProgramData\Anaconda3\envs\bank\lib\site-packages\pymysql\cursors.py", line 310, in _query
    conn.query(q)
  File "C:\ProgramData\Anaconda3\envs\bank\lib\site-packages\pymysql\connections.py", line 548, in query
    self._affected_rows = self._read_query_result(unbuffered=unbuffered)
  File "C:\ProgramData\Anaconda3\envs\bank\lib\site-packages\pymysql\connections.py", line 775, in _read_query_result
    result.read()
  File "C:\ProgramData\Anaconda3\envs\bank\lib\site-packages\pymysql\connections.py", line 1156, in read
    first_packet = self.connection._read_packet()
  File "C:\ProgramData\Anaconda3\envs\bank\lib\site-packages\pymysql\connections.py", line 725, in _read_packet
    packet.raise_for_error()
  File "C:\ProgramData\Anaconda3\envs\bank\lib\site-packages\pymysql\protocol.py", line 221, in raise_for_error
    err.raise_mysql_exception(self._data)
  File "C:\ProgramData\Anaconda3\envs\bank\lib\site-packages\pymysql\err.py", line 143, in raise_mysql_exception
    raise errorclass(errno, errval)
pymysql.err.OperationalError: (1054, "Unknown column 'status' in 'field list'")

The above exception was the direct cause of the following exception:

Traceback (most recent call last):
  File "C:\Users\huang\OneDrive\14-code\bank\database.py", line 89, in new_rec_in_db
    session.commit()
  File "C:\ProgramData\Anaconda3\envs\bank\lib\site-packages\sqlalchemy\orm\session.py", line 1428, in commit
    self._transaction.commit(_to_root=self.future)
  File "C:\ProgramData\Anaconda3\envs\bank\lib\site-packages\sqlalchemy\orm\session.py", line 829, in commit
    self._prepare_impl()
  File "C:\ProgramData\Anaconda3\envs\bank\lib\site-packages\sqlalchemy\orm\session.py", line 808, in _prepare_impl
    self.session.flush()
  File "C:\ProgramData\Anaconda3\envs\bank\lib\site-packages\sqlalchemy\orm\session.py", line 3345, in flush
    self._flush(objects)
  File "C:\ProgramData\Anaconda3\envs\bank\lib\site-packages\sqlalchemy\orm\session.py", line 3485, in _flush
    transaction.rollback(_capture_exception=True)
  File "C:\ProgramData\Anaconda3\envs\bank\lib\site-packages\sqlalchemy\util\langhelpers.py", line 70, in __exit__
    compat.raise_(
  File "C:\ProgramData\Anaconda3\envs\bank\lib\site-packages\sqlalchemy\util\compat.py", line 207, in raise_
    raise exception
  File "C:\ProgramData\Anaconda3\envs\bank\lib\site-packages\sqlalchemy\orm\session.py", line 3445, in _flush
    flush_context.execute()
  File "C:\ProgramData\Anaconda3\envs\bank\lib\site-packages\sqlalchemy\orm\unitofwork.py", line 456, in execute
    rec.execute(self)
  File "C:\ProgramData\Anaconda3\envs\bank\lib\site-packages\sqlalchemy\orm\unitofwork.py", line 630, in execute
    util.preloaded.orm_persistence.save_obj(
  File "C:\ProgramData\Anaconda3\envs\bank\lib\site-packages\sqlalchemy\orm\persistence.py", line 244, in save_obj
    _emit_insert_statements(
  File "C:\ProgramData\Anaconda3\envs\bank\lib\site-packages\sqlalchemy\orm\persistence.py", line 1221, in _emit_insert_statements
    result = connection._execute_20(
  File "C:\ProgramData\Anaconda3\envs\bank\lib\site-packages\sqlalchemy\engine\base.py", line 1614, in _execute_20
    return meth(self, args_10style, kwargs_10style, execution_options)
  File "C:\ProgramData\Anaconda3\envs\bank\lib\site-packages\sqlalchemy\sql\elements.py", line 325, in _execute_on_connection
    return connection._execute_clauseelement(
  File "C:\ProgramData\Anaconda3\envs\bank\lib\site-packages\sqlalchemy\engine\base.py", line 1481, in _execute_clauseelement
    ret = self._execute_context(
  File "C:\ProgramData\Anaconda3\envs\bank\lib\site-packages\sqlalchemy\engine\base.py", line 1845, in _execute_context
    self._handle_dbapi_exception(
  File "C:\ProgramData\Anaconda3\envs\bank\lib\site-packages\sqlalchemy\engine\base.py", line 2026, in _handle_dbapi_exception
    util.raise_(
  File "C:\ProgramData\Anaconda3\envs\bank\lib\site-packages\sqlalchemy\util\compat.py", line 207, in raise_
    raise exception
  File "C:\ProgramData\Anaconda3\envs\bank\lib\site-packages\sqlalchemy\engine\base.py", line 1802, in _execute_context
    self.dialect.do_execute(
  File "C:\ProgramData\Anaconda3\envs\bank\lib\site-packages\sqlalchemy\engine\default.py", line 719, in do_execute
    cursor.execute(statement, parameters)
  File "C:\ProgramData\Anaconda3\envs\bank\lib\site-packages\pymysql\cursors.py", line 148, in execute
    result = self._query(query)
  File "C:\ProgramData\Anaconda3\envs\bank\lib\site-packages\pymysql\cursors.py", line 310, in _query
    conn.query(q)
  File "C:\ProgramData\Anaconda3\envs\bank\lib\site-packages\pymysql\connections.py", line 548, in query
    self._affected_rows = self._read_query_result(unbuffered=unbuffered)
  File "C:\ProgramData\Anaconda3\envs\bank\lib\site-packages\pymysql\connections.py", line 775, in _read_query_result
    result.read()
  File "C:\ProgramData\Anaconda3\envs\bank\lib\site-packages\pymysql\connections.py", line 1156, in read
    first_packet = self.connection._read_packet()
  File "C:\ProgramData\Anaconda3\envs\bank\lib\site-packages\pymysql\connections.py", line 725, in _read_packet
    packet.raise_for_error()
  File "C:\ProgramData\Anaconda3\envs\bank\lib\site-packages\pymysql\protocol.py", line 221, in raise_for_error
    err.raise_mysql_exception(self._data)
  File "C:\ProgramData\Anaconda3\envs\bank\lib\site-packages\pymysql\err.py", line 143, in raise_mysql_exception
    raise errorclass(errno, errval)
sqlalchemy.exc.OperationalError: (pymysql.err.OperationalError) (1054, "Unknown column 'status' in 'field list'")
[SQL: INSERT INTO creditcard (customer_id, status, note, employee_id, app_date, apprv_date, card_id) VALUES (%(customer_id)s, %(status)s, %(note)s, %(employee_id)s, %(app_date)s, %(apprv_date)s, %(card_id)s)]
[parameters: {'customer_id': 100, 'status': None, 'note': None, 'employee_id': None, 'app_date': datetime.datetime(2022, 2, 4, 22, 32, 34, 89179), 'apprv_date': None, 'card_id': None}]
(Background on this error at: https://sqlalche.me/e/14/e3q8)
2022-02-04 22:37:37,177:utility.py:logger_expt:ERROR:(pymysql.err.OperationalError) (1054, "Unknown column 'status' in 'field list'")
[SQL: INSERT INTO creditcard (customer_id, status, note, employee_id, app_date, apprv_date, card_id) VALUES (%(customer_id)s, %(status)s, %(note)s, %(employee_id)s, %(app_date)s, %(apprv_date)s, %(card_id)s)]
[parameters: {'customer_id': 100, 'status': None, 'note': None, 'employee_id': None, 'app_date': datetime.datetime(2022, 2, 4, 22, 37, 37, 146523), 'apprv_date': None, 'card_id': None}]
(Background on this error at: https://sqlalche.me/e/14/e3q8)
Traceback (most recent call last):
  File "C:\ProgramData\Anaconda3\envs\bank\lib\site-packages\sqlalchemy\engine\base.py", line 1802, in _execute_context
    self.dialect.do_execute(
  File "C:\ProgramData\Anaconda3\envs\bank\lib\site-packages\sqlalchemy\engine\default.py", line 719, in do_execute
    cursor.execute(statement, parameters)
  File "C:\ProgramData\Anaconda3\envs\bank\lib\site-packages\pymysql\cursors.py", line 148, in execute
    result = self._query(query)
  File "C:\ProgramData\Anaconda3\envs\bank\lib\site-packages\pymysql\cursors.py", line 310, in _query
    conn.query(q)
  File "C:\ProgramData\Anaconda3\envs\bank\lib\site-packages\pymysql\connections.py", line 548, in query
    self._affected_rows = self._read_query_result(unbuffered=unbuffered)
  File "C:\ProgramData\Anaconda3\envs\bank\lib\site-packages\pymysql\connections.py", line 775, in _read_query_result
    result.read()
  File "C:\ProgramData\Anaconda3\envs\bank\lib\site-packages\pymysql\connections.py", line 1156, in read
    first_packet = self.connection._read_packet()
  File "C:\ProgramData\Anaconda3\envs\bank\lib\site-packages\pymysql\connections.py", line 725, in _read_packet
    packet.raise_for_error()
  File "C:\ProgramData\Anaconda3\envs\bank\lib\site-packages\pymysql\protocol.py", line 221, in raise_for_error
    err.raise_mysql_exception(self._data)
  File "C:\ProgramData\Anaconda3\envs\bank\lib\site-packages\pymysql\err.py", line 143, in raise_mysql_exception
    raise errorclass(errno, errval)
pymysql.err.OperationalError: (1054, "Unknown column 'status' in 'field list'")

The above exception was the direct cause of the following exception:

Traceback (most recent call last):
  File "C:\Users\huang\OneDrive\14-code\bank\database.py", line 89, in new_rec_in_db
    session.commit()
  File "C:\ProgramData\Anaconda3\envs\bank\lib\site-packages\sqlalchemy\orm\session.py", line 1428, in commit
    self._transaction.commit(_to_root=self.future)
  File "C:\ProgramData\Anaconda3\envs\bank\lib\site-packages\sqlalchemy\orm\session.py", line 829, in commit
    self._prepare_impl()
  File "C:\ProgramData\Anaconda3\envs\bank\lib\site-packages\sqlalchemy\orm\session.py", line 808, in _prepare_impl
    self.session.flush()
  File "C:\ProgramData\Anaconda3\envs\bank\lib\site-packages\sqlalchemy\orm\session.py", line 3345, in flush
    self._flush(objects)
  File "C:\ProgramData\Anaconda3\envs\bank\lib\site-packages\sqlalchemy\orm\session.py", line 3485, in _flush
    transaction.rollback(_capture_exception=True)
  File "C:\ProgramData\Anaconda3\envs\bank\lib\site-packages\sqlalchemy\util\langhelpers.py", line 70, in __exit__
    compat.raise_(
  File "C:\ProgramData\Anaconda3\envs\bank\lib\site-packages\sqlalchemy\util\compat.py", line 207, in raise_
    raise exception
  File "C:\ProgramData\Anaconda3\envs\bank\lib\site-packages\sqlalchemy\orm\session.py", line 3445, in _flush
    flush_context.execute()
  File "C:\ProgramData\Anaconda3\envs\bank\lib\site-packages\sqlalchemy\orm\unitofwork.py", line 456, in execute
    rec.execute(self)
  File "C:\ProgramData\Anaconda3\envs\bank\lib\site-packages\sqlalchemy\orm\unitofwork.py", line 630, in execute
    util.preloaded.orm_persistence.save_obj(
  File "C:\ProgramData\Anaconda3\envs\bank\lib\site-packages\sqlalchemy\orm\persistence.py", line 244, in save_obj
    _emit_insert_statements(
  File "C:\ProgramData\Anaconda3\envs\bank\lib\site-packages\sqlalchemy\orm\persistence.py", line 1221, in _emit_insert_statements
    result = connection._execute_20(
  File "C:\ProgramData\Anaconda3\envs\bank\lib\site-packages\sqlalchemy\engine\base.py", line 1614, in _execute_20
    return meth(self, args_10style, kwargs_10style, execution_options)
  File "C:\ProgramData\Anaconda3\envs\bank\lib\site-packages\sqlalchemy\sql\elements.py", line 325, in _execute_on_connection
    return connection._execute_clauseelement(
  File "C:\ProgramData\Anaconda3\envs\bank\lib\site-packages\sqlalchemy\engine\base.py", line 1481, in _execute_clauseelement
    ret = self._execute_context(
  File "C:\ProgramData\Anaconda3\envs\bank\lib\site-packages\sqlalchemy\engine\base.py", line 1845, in _execute_context
    self._handle_dbapi_exception(
  File "C:\ProgramData\Anaconda3\envs\bank\lib\site-packages\sqlalchemy\engine\base.py", line 2026, in _handle_dbapi_exception
    util.raise_(
  File "C:\ProgramData\Anaconda3\envs\bank\lib\site-packages\sqlalchemy\util\compat.py", line 207, in raise_
    raise exception
  File "C:\ProgramData\Anaconda3\envs\bank\lib\site-packages\sqlalchemy\engine\base.py", line 1802, in _execute_context
    self.dialect.do_execute(
  File "C:\ProgramData\Anaconda3\envs\bank\lib\site-packages\sqlalchemy\engine\default.py", line 719, in do_execute
    cursor.execute(statement, parameters)
  File "C:\ProgramData\Anaconda3\envs\bank\lib\site-packages\pymysql\cursors.py", line 148, in execute
    result = self._query(query)
  File "C:\ProgramData\Anaconda3\envs\bank\lib\site-packages\pymysql\cursors.py", line 310, in _query
    conn.query(q)
  File "C:\ProgramData\Anaconda3\envs\bank\lib\site-packages\pymysql\connections.py", line 548, in query
    self._affected_rows = self._read_query_result(unbuffered=unbuffered)
  File "C:\ProgramData\Anaconda3\envs\bank\lib\site-packages\pymysql\connections.py", line 775, in _read_query_result
    result.read()
  File "C:\ProgramData\Anaconda3\envs\bank\lib\site-packages\pymysql\connections.py", line 1156, in read
    first_packet = self.connection._read_packet()
  File "C:\ProgramData\Anaconda3\envs\bank\lib\site-packages\pymysql\connections.py", line 725, in _read_packet
    packet.raise_for_error()
  File "C:\ProgramData\Anaconda3\envs\bank\lib\site-packages\pymysql\protocol.py", line 221, in raise_for_error
    err.raise_mysql_exception(self._data)
  File "C:\ProgramData\Anaconda3\envs\bank\lib\site-packages\pymysql\err.py", line 143, in raise_mysql_exception
    raise errorclass(errno, errval)
sqlalchemy.exc.OperationalError: (pymysql.err.OperationalError) (1054, "Unknown column 'status' in 'field list'")
[SQL: INSERT INTO creditcard (customer_id, status, note, employee_id, app_date, apprv_date, card_id) VALUES (%(customer_id)s, %(status)s, %(note)s, %(employee_id)s, %(app_date)s, %(apprv_date)s, %(card_id)s)]
[parameters: {'customer_id': 100, 'status': None, 'note': None, 'employee_id': None, 'app_date': datetime.datetime(2022, 2, 4, 22, 37, 37, 146523), 'apprv_date': None, 'card_id': None}]
(Background on this error at: https://sqlalche.me/e/14/e3q8)
2022-02-05 05:48:23,919:utility.py:logger_expt:ERROR:(pymysql.err.OperationalError) (1054, "Unknown column '_password' in 'field list'")
[SQL: INSERT INTO employee (name, login, _password) VALUES (%(name)s, %(login)s, %(_password)s)]
[parameters: {'name': 'jerry', 'login': 'a0582', '_password': 44571}]
(Background on this error at: https://sqlalche.me/e/14/e3q8)
Traceback (most recent call last):
  File "C:\ProgramData\Anaconda3\envs\bank\lib\site-packages\sqlalchemy\engine\base.py", line 1802, in _execute_context
    self.dialect.do_execute(
  File "C:\ProgramData\Anaconda3\envs\bank\lib\site-packages\sqlalchemy\engine\default.py", line 719, in do_execute
    cursor.execute(statement, parameters)
  File "C:\ProgramData\Anaconda3\envs\bank\lib\site-packages\pymysql\cursors.py", line 148, in execute
    result = self._query(query)
  File "C:\ProgramData\Anaconda3\envs\bank\lib\site-packages\pymysql\cursors.py", line 310, in _query
    conn.query(q)
  File "C:\ProgramData\Anaconda3\envs\bank\lib\site-packages\pymysql\connections.py", line 548, in query
    self._affected_rows = self._read_query_result(unbuffered=unbuffered)
  File "C:\ProgramData\Anaconda3\envs\bank\lib\site-packages\pymysql\connections.py", line 775, in _read_query_result
    result.read()
  File "C:\ProgramData\Anaconda3\envs\bank\lib\site-packages\pymysql\connections.py", line 1156, in read
    first_packet = self.connection._read_packet()
  File "C:\ProgramData\Anaconda3\envs\bank\lib\site-packages\pymysql\connections.py", line 725, in _read_packet
    packet.raise_for_error()
  File "C:\ProgramData\Anaconda3\envs\bank\lib\site-packages\pymysql\protocol.py", line 221, in raise_for_error
    err.raise_mysql_exception(self._data)
  File "C:\ProgramData\Anaconda3\envs\bank\lib\site-packages\pymysql\err.py", line 143, in raise_mysql_exception
    raise errorclass(errno, errval)
pymysql.err.OperationalError: (1054, "Unknown column '_password' in 'field list'")

The above exception was the direct cause of the following exception:

Traceback (most recent call last):
  File "C:\Users\huang\OneDrive\14-code\bank\database.py", line 89, in new_rec_in_db
    session.commit()
  File "C:\ProgramData\Anaconda3\envs\bank\lib\site-packages\sqlalchemy\orm\session.py", line 1428, in commit
    self._transaction.commit(_to_root=self.future)
  File "C:\ProgramData\Anaconda3\envs\bank\lib\site-packages\sqlalchemy\orm\session.py", line 829, in commit
    self._prepare_impl()
  File "C:\ProgramData\Anaconda3\envs\bank\lib\site-packages\sqlalchemy\orm\session.py", line 808, in _prepare_impl
    self.session.flush()
  File "C:\ProgramData\Anaconda3\envs\bank\lib\site-packages\sqlalchemy\orm\session.py", line 3345, in flush
    self._flush(objects)
  File "C:\ProgramData\Anaconda3\envs\bank\lib\site-packages\sqlalchemy\orm\session.py", line 3485, in _flush
    transaction.rollback(_capture_exception=True)
  File "C:\ProgramData\Anaconda3\envs\bank\lib\site-packages\sqlalchemy\util\langhelpers.py", line 70, in __exit__
    compat.raise_(
  File "C:\ProgramData\Anaconda3\envs\bank\lib\site-packages\sqlalchemy\util\compat.py", line 207, in raise_
    raise exception
  File "C:\ProgramData\Anaconda3\envs\bank\lib\site-packages\sqlalchemy\orm\session.py", line 3445, in _flush
    flush_context.execute()
  File "C:\ProgramData\Anaconda3\envs\bank\lib\site-packages\sqlalchemy\orm\unitofwork.py", line 456, in execute
    rec.execute(self)
  File "C:\ProgramData\Anaconda3\envs\bank\lib\site-packages\sqlalchemy\orm\unitofwork.py", line 630, in execute
    util.preloaded.orm_persistence.save_obj(
  File "C:\ProgramData\Anaconda3\envs\bank\lib\site-packages\sqlalchemy\orm\persistence.py", line 244, in save_obj
    _emit_insert_statements(
  File "C:\ProgramData\Anaconda3\envs\bank\lib\site-packages\sqlalchemy\orm\persistence.py", line 1221, in _emit_insert_statements
    result = connection._execute_20(
  File "C:\ProgramData\Anaconda3\envs\bank\lib\site-packages\sqlalchemy\engine\base.py", line 1614, in _execute_20
    return meth(self, args_10style, kwargs_10style, execution_options)
  File "C:\ProgramData\Anaconda3\envs\bank\lib\site-packages\sqlalchemy\sql\elements.py", line 325, in _execute_on_connection
    return connection._execute_clauseelement(
  File "C:\ProgramData\Anaconda3\envs\bank\lib\site-packages\sqlalchemy\engine\base.py", line 1481, in _execute_clauseelement
    ret = self._execute_context(
  File "C:\ProgramData\Anaconda3\envs\bank\lib\site-packages\sqlalchemy\engine\base.py", line 1845, in _execute_context
    self._handle_dbapi_exception(
  File "C:\ProgramData\Anaconda3\envs\bank\lib\site-packages\sqlalchemy\engine\base.py", line 2026, in _handle_dbapi_exception
    util.raise_(
  File "C:\ProgramData\Anaconda3\envs\bank\lib\site-packages\sqlalchemy\util\compat.py", line 207, in raise_
    raise exception
  File "C:\ProgramData\Anaconda3\envs\bank\lib\site-packages\sqlalchemy\engine\base.py", line 1802, in _execute_context
    self.dialect.do_execute(
  File "C:\ProgramData\Anaconda3\envs\bank\lib\site-packages\sqlalchemy\engine\default.py", line 719, in do_execute
    cursor.execute(statement, parameters)
  File "C:\ProgramData\Anaconda3\envs\bank\lib\site-packages\pymysql\cursors.py", line 148, in execute
    result = self._query(query)
  File "C:\ProgramData\Anaconda3\envs\bank\lib\site-packages\pymysql\cursors.py", line 310, in _query
    conn.query(q)
  File "C:\ProgramData\Anaconda3\envs\bank\lib\site-packages\pymysql\connections.py", line 548, in query
    self._affected_rows = self._read_query_result(unbuffered=unbuffered)
  File "C:\ProgramData\Anaconda3\envs\bank\lib\site-packages\pymysql\connections.py", line 775, in _read_query_result
    result.read()
  File "C:\ProgramData\Anaconda3\envs\bank\lib\site-packages\pymysql\connections.py", line 1156, in read
    first_packet = self.connection._read_packet()
  File "C:\ProgramData\Anaconda3\envs\bank\lib\site-packages\pymysql\connections.py", line 725, in _read_packet
    packet.raise_for_error()
  File "C:\ProgramData\Anaconda3\envs\bank\lib\site-packages\pymysql\protocol.py", line 221, in raise_for_error
    err.raise_mysql_exception(self._data)
  File "C:\ProgramData\Anaconda3\envs\bank\lib\site-packages\pymysql\err.py", line 143, in raise_mysql_exception
    raise errorclass(errno, errval)
sqlalchemy.exc.OperationalError: (pymysql.err.OperationalError) (1054, "Unknown column '_password' in 'field list'")
[SQL: INSERT INTO employee (name, login, _password) VALUES (%(name)s, %(login)s, %(_password)s)]
[parameters: {'name': 'jerry', 'login': 'a0582', '_password': 44571}]
(Background on this error at: https://sqlalche.me/e/14/e3q8)
2022-02-05 05:52:57,201:utility.py:logger_expt:ERROR:(pymysql.err.OperationalError) (1054, "Unknown column '_password' in 'field list'")
[SQL: INSERT INTO employee (name, login, _password) VALUES (%(name)s, %(login)s, %(_password)s)]
[parameters: {'name': 'jerry', 'login': 'a0588', '_password': None}]
(Background on this error at: https://sqlalche.me/e/14/e3q8)
Traceback (most recent call last):
  File "C:\ProgramData\Anaconda3\envs\bank\lib\site-packages\sqlalchemy\engine\base.py", line 1802, in _execute_context
    self.dialect.do_execute(
  File "C:\ProgramData\Anaconda3\envs\bank\lib\site-packages\sqlalchemy\engine\default.py", line 719, in do_execute
    cursor.execute(statement, parameters)
  File "C:\ProgramData\Anaconda3\envs\bank\lib\site-packages\pymysql\cursors.py", line 148, in execute
    result = self._query(query)
  File "C:\ProgramData\Anaconda3\envs\bank\lib\site-packages\pymysql\cursors.py", line 310, in _query
    conn.query(q)
  File "C:\ProgramData\Anaconda3\envs\bank\lib\site-packages\pymysql\connections.py", line 548, in query
    self._affected_rows = self._read_query_result(unbuffered=unbuffered)
  File "C:\ProgramData\Anaconda3\envs\bank\lib\site-packages\pymysql\connections.py", line 775, in _read_query_result
    result.read()
  File "C:\ProgramData\Anaconda3\envs\bank\lib\site-packages\pymysql\connections.py", line 1156, in read
    first_packet = self.connection._read_packet()
  File "C:\ProgramData\Anaconda3\envs\bank\lib\site-packages\pymysql\connections.py", line 725, in _read_packet
    packet.raise_for_error()
  File "C:\ProgramData\Anaconda3\envs\bank\lib\site-packages\pymysql\protocol.py", line 221, in raise_for_error
    err.raise_mysql_exception(self._data)
  File "C:\ProgramData\Anaconda3\envs\bank\lib\site-packages\pymysql\err.py", line 143, in raise_mysql_exception
    raise errorclass(errno, errval)
pymysql.err.OperationalError: (1054, "Unknown column '_password' in 'field list'")

The above exception was the direct cause of the following exception:

Traceback (most recent call last):
  File "C:\Users\huang\OneDrive\14-code\bank\database.py", line 89, in new_rec_in_db
    session.commit()
  File "C:\ProgramData\Anaconda3\envs\bank\lib\site-packages\sqlalchemy\orm\session.py", line 1428, in commit
    self._transaction.commit(_to_root=self.future)
  File "C:\ProgramData\Anaconda3\envs\bank\lib\site-packages\sqlalchemy\orm\session.py", line 829, in commit
    self._prepare_impl()
  File "C:\ProgramData\Anaconda3\envs\bank\lib\site-packages\sqlalchemy\orm\session.py", line 808, in _prepare_impl
    self.session.flush()
  File "C:\ProgramData\Anaconda3\envs\bank\lib\site-packages\sqlalchemy\orm\session.py", line 3345, in flush
    self._flush(objects)
  File "C:\ProgramData\Anaconda3\envs\bank\lib\site-packages\sqlalchemy\orm\session.py", line 3485, in _flush
    transaction.rollback(_capture_exception=True)
  File "C:\ProgramData\Anaconda3\envs\bank\lib\site-packages\sqlalchemy\util\langhelpers.py", line 70, in __exit__
    compat.raise_(
  File "C:\ProgramData\Anaconda3\envs\bank\lib\site-packages\sqlalchemy\util\compat.py", line 207, in raise_
    raise exception
  File "C:\ProgramData\Anaconda3\envs\bank\lib\site-packages\sqlalchemy\orm\session.py", line 3445, in _flush
    flush_context.execute()
  File "C:\ProgramData\Anaconda3\envs\bank\lib\site-packages\sqlalchemy\orm\unitofwork.py", line 456, in execute
    rec.execute(self)
  File "C:\ProgramData\Anaconda3\envs\bank\lib\site-packages\sqlalchemy\orm\unitofwork.py", line 630, in execute
    util.preloaded.orm_persistence.save_obj(
  File "C:\ProgramData\Anaconda3\envs\bank\lib\site-packages\sqlalchemy\orm\persistence.py", line 244, in save_obj
    _emit_insert_statements(
  File "C:\ProgramData\Anaconda3\envs\bank\lib\site-packages\sqlalchemy\orm\persistence.py", line 1221, in _emit_insert_statements
    result = connection._execute_20(
  File "C:\ProgramData\Anaconda3\envs\bank\lib\site-packages\sqlalchemy\engine\base.py", line 1614, in _execute_20
    return meth(self, args_10style, kwargs_10style, execution_options)
  File "C:\ProgramData\Anaconda3\envs\bank\lib\site-packages\sqlalchemy\sql\elements.py", line 325, in _execute_on_connection
    return connection._execute_clauseelement(
  File "C:\ProgramData\Anaconda3\envs\bank\lib\site-packages\sqlalchemy\engine\base.py", line 1481, in _execute_clauseelement
    ret = self._execute_context(
  File "C:\ProgramData\Anaconda3\envs\bank\lib\site-packages\sqlalchemy\engine\base.py", line 1845, in _execute_context
    self._handle_dbapi_exception(
  File "C:\ProgramData\Anaconda3\envs\bank\lib\site-packages\sqlalchemy\engine\base.py", line 2026, in _handle_dbapi_exception
    util.raise_(
  File "C:\ProgramData\Anaconda3\envs\bank\lib\site-packages\sqlalchemy\util\compat.py", line 207, in raise_
    raise exception
  File "C:\ProgramData\Anaconda3\envs\bank\lib\site-packages\sqlalchemy\engine\base.py", line 1802, in _execute_context
    self.dialect.do_execute(
  File "C:\ProgramData\Anaconda3\envs\bank\lib\site-packages\sqlalchemy\engine\default.py", line 719, in do_execute
    cursor.execute(statement, parameters)
  File "C:\ProgramData\Anaconda3\envs\bank\lib\site-packages\pymysql\cursors.py", line 148, in execute
    result = self._query(query)
  File "C:\ProgramData\Anaconda3\envs\bank\lib\site-packages\pymysql\cursors.py", line 310, in _query
    conn.query(q)
  File "C:\ProgramData\Anaconda3\envs\bank\lib\site-packages\pymysql\connections.py", line 548, in query
    self._affected_rows = self._read_query_result(unbuffered=unbuffered)
  File "C:\ProgramData\Anaconda3\envs\bank\lib\site-packages\pymysql\connections.py", line 775, in _read_query_result
    result.read()
  File "C:\ProgramData\Anaconda3\envs\bank\lib\site-packages\pymysql\connections.py", line 1156, in read
    first_packet = self.connection._read_packet()
  File "C:\ProgramData\Anaconda3\envs\bank\lib\site-packages\pymysql\connections.py", line 725, in _read_packet
    packet.raise_for_error()
  File "C:\ProgramData\Anaconda3\envs\bank\lib\site-packages\pymysql\protocol.py", line 221, in raise_for_error
    err.raise_mysql_exception(self._data)
  File "C:\ProgramData\Anaconda3\envs\bank\lib\site-packages\pymysql\err.py", line 143, in raise_mysql_exception
    raise errorclass(errno, errval)
sqlalchemy.exc.OperationalError: (pymysql.err.OperationalError) (1054, "Unknown column '_password' in 'field list'")
[SQL: INSERT INTO employee (name, login, _password) VALUES (%(name)s, %(login)s, %(_password)s)]
[parameters: {'name': 'jerry', 'login': 'a0588', '_password': None}]
(Background on this error at: https://sqlalche.me/e/14/e3q8)
